Workbook

Sheet Verificacao
A1: PLANILHA INDEPENDENTE DE VERIFICAÇÃO DO SIMULADOR – BALANÇO HÍDRICO MENSAL
A3: USO: cole a série histórica 1910–2021 em Vazoes_COLAR (A1:M113) e selecione o reservatório em B6. O balanço começa automaticamente no primeiro mês que possuir vazão. Assim, se jan–out/1910 estiverem vazios e nov/1910 for o primeiro dado, jan–out são ignorados e o volume inicial de B11 é aplicado em nov/1910.
A5: PARÂMETRO | B5: VALOR | D5: INDICADOR | E5: RESULTADO | G5: LÓGICA REPRODUZIDA
A6: Reservatório | B6: Mundaú | D6: Meses válidos | E6: =COUNT($D$24:$D$1367) -> 2 | G6: Mês de 30 dias; Q convertido por 2,592 hm³/mês; interpolação linear na CAV; evaporação calculada com área média entre a área inicial e a área da primeira estimativa; retirada limitada pela disponibilidade; excedente acima da capacidade vira vertimento. | K6: jan/1910 a dez/2021
A7: Código | B7: {=IFERROR(INDEX(Dados_Acudes!$B$2:$B$156,MATCH(B6,Dados_Acudes!$A$2:$A$156,0)),"")} -> 61 | D7: Falhas | E7: =COUNTIF($V$24:$V$1367,"Sim") -> 0 | K7: Automático no primeiro mês com vazão
A8: Capacidade (hm³) | B8: {=IFERROR(INDEX(Dados_Acudes!$C$2:$C$156,MATCH(B6,Dados_Acudes!$A$2:$A$156,0))/1000000,"")} -> 21.3 | D8: Atendimento global (%) | E8: =IFERROR(SUM($Q$24:$Q$1367)/SUM($K$24:$K$1367)*100,0) -> 100 | K8: {=IFERROR(INDEX($A$24:$A$1367,MATCH(1,$AC$24:$AC$1367,0)),"")} -> 3958
A9: Estação de evaporação | B9: {=IFERROR(INDEX(Dados_Acudes!$F$2:$F$156,MATCH(B6,Dados_Acudes!$A$2:$A$156,0)),"")} -> 13 | D9: Vertimento total (hm³) | E9: =SUM($T$24:$T$1367) -> 0 | K9: =IF(E6=0,"",LOOKUP(2,1/($D$24:$D$1367<>""),$A$24:$A$1367)) -> #N/A
A10: Volume inicial (% capacidade) | B10: 50 | D10: Evaporação total (hm³) | E10: =SUM($O$24:$O$1367) -> 0.40001042 | K10: =IF(K8="","",(YEAR(K8)-1910)*12+MONTH(K8)-1) -> 10
A11: Volume inicial (hm³) | B11: =B8*B10/100 -> 10.65 | D11: Resíduo máximo |ε| (hm³) | E11: =IF(E6=0,0,MAX($X$24:$X$1367)) -> 0 | K11: =E6 -> 2
A12: Demanda constante (m³/s) | B12: 0.5 | D12: Volume mínimo (hm³) | E12: =IF(E6=0,0,MIN($U$24:$U$1367)) -> 9.1448133 | K12: =IF(OR(K8="",K9=""),"",(YEAR(K9)-YEAR(K8))*12+MONTH(K9)-MONTH(K8)+1-E6) -> #N/A
A13: Demanda constante (L/s) | B13: =B12*1000 -> 500 | D13: Volume máximo (hm³) | E13: =IF(E6=0,0,MAX($U$24:$U$1367)) -> 9.1631763 | K13: =IF(E6=0,"SEM DADOS",IF(K12=0,"OK","VERIFICAR LACUNAS")) -> #N/A
A14: Dias por mês | B14: 30 | D14: Situação do balanço | E14: =IF(E11<=B19,"OK","VERIFICAR") -> OK
A15: Conversão m³/s → hm³/mês | B15: =B14*86400/1000000 -> 2.592
A16: CAV mín. (hm³) | B16: {=IFERROR(INDEX(Dados_CAV!$E:$E,B20),"")} -> 0 | D16: Volumes físicos negativos | E16: =COUNTIF($H$24:$H$1367,"<0")+COUNTIF($U$24:$U$1367,"<0") -> 0 | G16: Versão nativa para LibreOffice Calc, sem LET, MAP, SCAN, MAKEARRAY ou matrizes dinâmicas.
A17: CAV máx. (hm³) | B17: {=IFERROR(INDEX(Dados_CAV!$E:$E,B20+B21-1),"")} -> 44.45 | D17: Status limites físicos | E17: =IF(E16=0,"OK","ERRO") -> OK
A18: Pontos CAV | B18: =B21 -> 12
A19: Tolerância do resíduo (hm³) | B19: 1e-08
A20: Linha inicial CAV | B20: {=IFERROR(INDEX(Dados_Acudes!$K$2:$K$156,MATCH(B6,Dados_Acudes!$A$2:$A$156,0)),"")} -> 1177
A21: Quantidade linhas CAV | B21: {=IFERROR(INDEX(Dados_Acudes!$L$2:$L$156,MATCH(B6,Dados_Acudes!$A$2:$A$156,0)),0)} -> 12
A23: Data | B23: Ano | C23: Mês nº | D23: Vazão (m³/s) | E23: Afluência (hm³) | F23: Evap. (mm) | G23: Evap. (m) | H23: Armaz. inicial (hm³) | I23: Área inicial (km²) | J23: Dem. solicitada (m³/s) | K23: Dem. solicitada (hm³) | L23: Saldo interno 1 (hm³) | M23: Área preliminar (km²) | N23: Área média (km²) | O23: Evaporação (hm³) | P23: Saldo interno 2 (hm³) | Q23: Retirada efetiva (hm³) | R23: Dem. atendida (m³/s) | S23: Déficit (m³/s) | T23: Vertimento (hm³) | U23: Armaz. final (hm³) | V23: Falha | W23: Resíduo ε (hm³) | X23: |ε| (hm³) | Y23: Volume final (%) | Z23: Estado interno auxiliar (hm³)
A24: =IF(D24="","",DATE(B24,C24,1)) | B24: {=IF(D24="","",IFERROR(VALUE(INDEX(Vazoes_COLAR!$A$2:$A$200,INT((ROW()-24)/12)+1)),""))} | C24: =IF(D24="","",MOD(ROW()-24,12)+1) | D24: {=IF(ISBLANK(INDEX(Vazoes_COLAR!$B$2:$M$200,INT((ROW()-24)/12)+1,MOD(ROW()-24,12)+1)),"",IF(ISNUMBER(INDEX(Vazoes_COLAR!$B$2:$M$200,INT((ROW()-24)/12)+1,MOD(ROW()-24,12)+1)),INDEX(Vazoes_COLAR!$B$2:$M$200,INT((ROW()-24)/12)+1,MOD(ROW()-24,12)+1),IFERROR(NUMBERVALUE(INDEX(Vazoes_COLAR!$B$2:$M$200,INT((ROW()-24)/12)+1,MOD(ROW()-24,12)+1),",","."),"")))} | E24: =IF(D24="","",D24*$B$15) | F24: {=IF(D24="","",IFERROR(INDEX(Dados_Evap!$C$2:$N$15,MATCH($B$9,Dados_Evap!$A$2:$A$15,0),C24),0))} | G24: =IF(F24="","",F24/1000) | H24: =IF(D24="","",MAX(0,MIN($B$8,$B$11))) | I24: {=IF(D24="","",IF(H24<=$B$16,INDEX(Aux_CAV!$B$2:$B$121,1),IF(H24>=$B$17,INDEX(Aux_CAV!$B$2:$B$121,$B$21),INDEX(Aux_CAV!$B$2:$B$121,AA24)+(H24-INDEX(Aux_CAV!$A$2:$A$121,AA24))*(INDEX(Aux_CAV!$B$2:$B$121,AA24+1)-INDEX(Aux_CAV!$B$2:$B$121,AA24))/(INDEX(Aux_CAV!$A$2:$A$121,AA24+1)-INDEX(Aux_CAV!$A$2:$A$121,AA24)))))} | J24: =IF(D24="","",$B$12) | K24: =IF(J24="","",J24*$B$15) | L24: =IF(D24="","",H24+E24-K24-G24*I24) | M24: {=IF(D24="","",IF(L24<=$B$16,INDEX(Aux_CAV!$B$2:$B$121,1),IF(L24>=$B$17,INDEX(Aux_CAV!$B$2:$B$121,$B$21),INDEX(Aux_CAV!$B$2:$B$121,AB24)+(L24-INDEX(Aux_CAV!$A$2:$A$121,AB24))*(INDEX(Aux_CAV!$B$2:$B$121,AB24+1)-INDEX(Aux_CAV!$B$2:$B$121,AB24))/(INDEX(Aux_CAV!$A$2:$A$121,AB24+1)-INDEX(Aux_CAV!$A$2:$A$121,AB24)))))} | N24: =IF(D24="","",(I24+M24)/2) | O24: =IF(D24="","",G24*N24) | P24: =IF(D24="","",H24+E24-K24-O24) | Q24: =IF(D24="","",IF(P24>=0,K24,MAX(0,K24+P24))) | R24: =IF(D24="","",Q24/$B$15) | S24: =IF(D24="","",MAX(0,J24-R24)) | T24: =IF(D24="","",MAX(0,Z24-$B$8)) | U24: =IF(D24="","",MAX(0,MIN($B$8,Z24))) | V24: =IF(D24="","",IF(S24>0.0000001,"Sim","Não")) | W24: =IF(D24="","",U24-(H24+E24-Q24-O24-T24)) | X24: =IF(W24="","",ABS(W24)) | Y24: =IF(U24="","",IF($B$8=0,0,U24/$B$8*100)) | Z24: =IF(D24="","",MAX(0,IF(P24>=0,P24,IF(K24+P24>=0,0,P24+K24)))) | AA24: =IF(D24="","",IF(H24<=$B$16,1,IF(H24>=$B$17,$B$21,MATCH(H24,Aux_CAV!$A$2:$A$121,1)))) | AB24: =IF(D24="","",IF(L24<=$B$16,1,IF(L24>=$B$17,$B$21,MATCH(L24,Aux_CAV!$A$2:$A$121,1)))) | AC24: =IF(D24="","",COUNT($D$24:D24))
A25: =IF(D25="","",DATE(B25,C25,1)) | B25: {=IF(D25="","",IFERROR(VALUE(INDEX(Vazoes_COLAR!$A$2:$A$200,INT((ROW()-24)/12)+1)),""))} | C25: =IF(D25="","",MOD(ROW()-24,12)+1) | D25: {=IF(ISBLANK(INDEX(Vazoes_COLAR!$B$2:$M$200,INT((ROW()-24)/12)+1,MOD(ROW()-24,12)+1)),"",IF(ISNUMBER(INDEX(Vazoes_COLAR!$B$2:$M$200,INT((ROW()-24)/12)+1,MOD(ROW()-24,12)+1)),INDEX(Vazoes_COLAR!$B$2:$M$200,INT((ROW()-24)/12)+1,MOD(ROW()-24,12)+1),IFERROR(NUMBERVALUE(INDEX(Vazoes_COLAR!$B$2:$M$200,INT((ROW()-24)/12)+1,MOD(ROW()-24,12)+1),",","."),"")))} | E25: =IF(D25="","",D25*$B$15) | F25: {=IF(D25="","",IFERROR(INDEX(Dados_Evap!$C$2:$N$15,MATCH($B$9,Dados_Evap!$A$2:$A$15,0),C25),0))} | G25: =IF(F25="","",F25/1000) | H25: =IF(D25="","",MAX(0,MIN($B$8,IFERROR(LOOKUP(2,1/($U$24:U24<>""),$U$24:U24),$B$11)))) | I25: {=IF(D25="","",IF(H25<=$B$16,INDEX(Aux_CAV!$B$2:$B$121,1),IF(H25>=$B$17,INDEX(Aux_CAV!$B$2:$B$121,$B$21),INDEX(Aux_CAV!$B$2:$B$121,AA25)+(H25-INDEX(Aux_CAV!$A$2:$A$121,AA25))*(INDEX(Aux_CAV!$B$2:$B$121,AA25+1)-INDEX(Aux_CAV!$B$2:$B$121,AA25))/(INDEX(Aux_CAV!$A$2:$A$121,AA25+1)-INDEX(Aux_CAV!$A$2:$A$121,AA25)))))} | J25: =IF(D25="","",$B$12) | K25: =IF(J25="","",J25*$B$15) | L25: =IF(D25="","",H25+E25-K25-G25*I25) | M25: {=IF(D25="","",IF(L25<=$B$16,INDEX(Aux_CAV!$B$2:$B$121,1),IF(L25>=$B$17,INDEX(Aux_CAV!$B$2:$B$121,$B$21),INDEX(Aux_CAV!$B$2:$B$121,AB25)+(L25-INDEX(Aux_CAV!$A$2:$A$121,AB25))*(INDEX(Aux_CAV!$B$2:$B$121,AB25+1)-INDEX(Aux_CAV!$B$2:$B$121,AB25))/(INDEX(Aux_CAV!$A$2:$A$121,AB25+1)-INDEX(Aux_CAV!$A$2:$A$121,AB25)))))} | N25: =IF(D25="","",(I25+M25)/2) | O25: =IF(D25="","",G25*N25) | P25: =IF(D25="","",H25+E25-K25-O25) | Q25: =IF(D25="","",IF(P25>=0,K25,MAX(0,K25+P25))) | R25: =IF(D25="","",Q25/$B$15) | S25: =IF(D25="","",MAX(0,J25-R25)) | T25: =IF(D25="","",MAX(0,Z25-$B$8)) | U25: =IF(D25="","",MAX(0,MIN($B$8,Z25))) | V25: =IF(D25="","",IF(S25>0.0000001,"Sim","Não")) | W25: =IF(D25="","",U25-(H25+E25-Q25-O25-T25)) | X25: =IF(W25="","",ABS(W25)) | Y25: =IF(U25="","",IF($B$8=0,0,U25/$B$8*100)) | Z25: =IF(D25="","",MAX(0,IF(P25>=0,P25,IF(K25+P25>=0,0,P25+K25)))) | AA25: =IF(D25="","",IF(H25<=$B$16,1,IF(H25>=$B$17,$B$21,MATCH(H25,Aux_CAV!$A$2:$A$121,1)))) | AB25: =IF(D25="","",IF(L25<=$B$16,1,IF(L25>=$B$17,$B$21,MATCH(L25,Aux_CAV!$A$2:$A$121,1)))) | AC25: =IF(D25="","",COUNT($D$24:D25))
A26: =IF(D26="","",DATE(B26,C26,1)) | B26: {=IF(D26="","",IFERROR(VALUE(INDEX(Vazoes_COLAR!$A$2:$A$200,INT((ROW()-24)/12)+1)),""))} | C26: =IF(D26="","",MOD(ROW()-24,12)+1) | D26: {=IF(ISBLANK(INDEX(Vazoes_COLAR!$B$2:$M$200,INT((ROW()-24)/12)+1,MOD(ROW()-24,12)+1)),"",IF(ISNUMBER(INDEX(Vazoes_COLAR!$B$2:$M$200,INT((ROW()-24)/12)+1,MOD(ROW()-24,12)+1)),INDEX(Vazoes_COLAR!$B$2:$M$200,INT((ROW()-24)/12)+1,MOD(ROW()-24,12)+1),IFERROR(NUMBERVALUE(INDEX(Vazoes_COLAR!$B$2:$M$200,INT((ROW()-24)/12)+1,MOD(ROW()-24,12)+1),",","."),"")))} | E26: =IF(D26="","",D26*$B$15) | F26: {=IF(D26="","",IFERROR(INDEX(Dados_Evap!$C$2:$N$15,MATCH($B$9,Dados_Evap!$A$2:$A$15,0),C26),0))} | G26: =IF(F26="","",F26/1000) | H26: =IF(D26="","",MAX(0,MIN($B$8,IFERROR(LOOKUP(2,1/($U$24:U25<>""),$U$24:U25),$B$11)))) | I26: {=IF(D26="","",IF(H26<=$B$16,INDEX(Aux_CAV!$B$2:$B$121,1),IF(H26>=$B$17,INDEX(Aux_CAV!$B$2:$B$121,$B$21),INDEX(Aux_CAV!$B$2:$B$121,AA26)+(H26-INDEX(Aux_CAV!$A$2:$A$121,AA26))*(INDEX(Aux_CAV!$B$2:$B$121,AA26+1)-INDEX(Aux_CAV!$B$2:$B$121,AA26))/(INDEX(Aux_CAV!$A$2:$A$121,AA26+1)-INDEX(Aux_CAV!$A$2:$A$121,AA26)))))} | J26: =IF(D26="","",$B$12) | K26: =IF(J26="","",J26*$B$15) | L26: =IF(D26="","",H26+E26-K26-G26*I26) | M26: {=IF(D26="","",IF(L26<=$B$16,INDEX(Aux_CAV!$B$2:$B$121,1),IF(L26>=$B$17,INDEX(Aux_CAV!$B$2:$B$121,$B$21),INDEX(Aux_CAV!$B$2:$B$121,AB26)+(L26-INDEX(Aux_CAV!$A$2:$A$121,AB26))*(INDEX(Aux_CAV!$B$2:$B$121,AB26+1)-INDEX(Aux_CAV!$B$2:$B$121,AB26))/(INDEX(Aux_CAV!$A$2:$A$121,AB26+1)-INDEX(Aux_CAV!$A$2:$A$121,AB26)))))} | N26: =IF(D26="","",(I26+M26)/2) | O26: =IF(D26="","",G26*N26) | P26: =IF(D26="","",H26+E26-K26-O26) | Q26: =IF(D26="","",IF(P26>=0,K26,MAX(0,K26+P26))) | R26: =IF(D26="","",Q26/$B$15) | S26: =IF(D26="","",MAX(0,J26-R26)) | T26: =IF(D26="","",MAX(0,Z26-$B$8)) | U26: =IF(D26="","",MAX(0,MIN($B$8,Z26))) | V26: =IF(D26="","",IF(S26>0.0000001,"Sim","Não")) | W26: =IF(D26="","",U26-(H26+E26-Q26-O26-T26)) | X26: =IF(W26="","",ABS(W26)) | Y26: =IF(U26="","",IF($B$8=0,0,U26/$B$8*100)) | Z26: =IF(D26="","",MAX(0,IF(P26>=0,P26,IF(K26+P26>=0,0,P26+K26)))) | AA26: =IF(D26="","",IF(H26<=$B$16,1,IF(H26>=$B$17,$B$21,MATCH(H26,Aux_CAV!$A$2:$A$121,1)))) | AB26: =IF(D26="","",IF(L26<=$B$16,1,IF(L26>=$B$17,$B$21,MATCH(L26,Aux_CAV!$A$2:$A$121,1)))) | AC26: =IF(D26="","",COUNT($D$24:D26))
A27: =IF(D27="","",DATE(B27,C27,1)) | B27: {=IF(D27="","",IFERROR(VALUE(INDEX(Vazoes_COLAR!$A$2:$A$200,INT((ROW()-24)/12)+1)),""))} | C27: =IF(D27="","",MOD(ROW()-24,12)+1) | D27: {=IF(ISBLANK(INDEX(Vazoes_COLAR!$B$2:$M$200,INT((ROW()-24)/12)+1,MOD(ROW()-24,12)+1)),"",IF(ISNUMBER(INDEX(Vazoes_COLAR!$B$2:$M$200,INT((ROW()-24)/12)+1,MOD(ROW()-24,12)+1)),INDEX(Vazoes_COLAR!$B$2:$M$200,INT((ROW()-24)/12)+1,MOD(ROW()-24,12)+1),IFERROR(NUMBERVALUE(INDEX(Vazoes_COLAR!$B$2:$M$200,INT((ROW()-24)/12)+1,MOD(ROW()-24,12)+1),",","."),"")))} | E27: =IF(D27="","",D27*$B$15) | F27: {=IF(D27="","",IFERROR(INDEX(Dados_Evap!$C$2:$N$15,MATCH($B$9,Dados_Evap!$A$2:$A$15,0),C27),0))} | G27: =IF(F27="","",F27/1000) | H27: =IF(D27="","",MAX(0,MIN($B$8,IFERROR(LOOKUP(2,1/($U$24:U26<>""),$U$24:U26),$B$11)))) | I27: {=IF(D27="","",IF(H27<=$B$16,INDEX(Aux_CAV!$B$2:$B$121,1),IF(H27>=$B$17,INDEX(Aux_CAV!$B$2:$B$121,$B$21),INDEX(Aux_CAV!$B$2:$B$121,AA27)+(H27-INDEX(Aux_CAV!$A$2:$A$121,AA27))*(INDEX(Aux_CAV!$B$2:$B$121,AA27+1)-INDEX(Aux_CAV!$B$2:$B$121,AA27))/(INDEX(Aux_CAV!$A$2:$A$121,AA27+1)-INDEX(Aux_CAV!$A$2:$A$121,AA27)))))} | J27: =IF(D27="","",$B$12) | K27: =IF(J27="","",J27*$B$15) | L27: =IF(D27="","",H27+E27-K27-G27*I27) | M27: {=IF(D27="","",IF(L27<=$B$16,INDEX(Aux_CAV!$B$2:$B$121,1),IF(L27>=$B$17,INDEX(Aux_CAV!$B$2:$B$121,$B$21),INDEX(Aux_CAV!$B$2:$B$121,AB27)+(L27-INDEX(Aux_CAV!$A$2:$A$121,AB27))*(INDEX(Aux_CAV!$B$2:$B$121,AB27+1)-INDEX(Aux_CAV!$B$2:$B$121,AB27))/(INDEX(Aux_CAV!$A$2:$A$121,AB27+1)-INDEX(Aux_CAV!$A$2:$A$121,AB27)))))} | N27: =IF(D27="","",(I27+M27)/2) | O27: =IF(D27="","",G27*N27) | P27: =IF(D27="","",H27+E27-K27-O27) | Q27: =IF(D27="","",IF(P27>=0,K27,MAX(0,K27+P27))) | R27: =IF(D27="","",Q27/$B$15) | S27: =IF(D27="","",MAX(0,J27-R27)) | T27: =IF(D27="","",MAX(0,Z27-$B$8)) | U27: =IF(D27="","",MAX(0,MIN($B$8,Z27))) | V27: =IF(D27="","",IF(S27>0.0000001,"Sim","Não")) | W27: =IF(D27="","",U27-(H27+E27-Q27-O27-T27)) | X27: =IF(W27="","",ABS(W27)) | Y27: =IF(U27="","",IF($B$8=0,0,U27/$B$8*100)) | Z27: =IF(D27="","",MAX(0,IF(P27>=0,P27,IF(K27+P27>=0,0,P27+K27)))) | AA27: =IF(D27="","",IF(H27<=$B$16,1,IF(H27>=$B$17,$B$21,MATCH(H27,Aux_CAV!$A$2:$A$121,1)))) | AB27: =IF(D27="","",IF(L27<=$B$16,1,IF(L27>=$B$17,$B$21,MATCH(L27,Aux_CAV!$A$2:$A$121,1)))) | AC27: =IF(D27="","",COUNT($D$24:D27))
A28: =IF(D28="","",DATE(B28,C28,1)) | B28: {=IF(D28="","",IFERROR(VALUE(INDEX(Vazoes_COLAR!$A$2:$A$200,INT((ROW()-24)/12)+1)),""))} | C28: =IF(D28="","",MOD(ROW()-24,12)+1) | D28: {=IF(ISBLANK(INDEX(Vazoes_COLAR!$B$2:$M$200,INT((ROW()-24)/12)+1,MOD(ROW()-24,12)+1)),"",IF(ISNUMBER(INDEX(Vazoes_COLAR!$B$2:$M$200,INT((ROW()-24)/12)+1,MOD(ROW()-24,12)+1)),INDEX(Vazoes_COLAR!$B$2:$M$200,INT((ROW()-24)/12)+1,MOD(ROW()-24,12)+1),IFERROR(NUMBERVALUE(INDEX(Vazoes_COLAR!$B$2:$M$200,INT((ROW()-24)/12)+1,MOD(ROW()-24,12)+1),",","."),"")))} | E28: =IF(D28="","",D28*$B$15) | F28: {=IF(D28="","",IFERROR(INDEX(Dados_Evap!$C$2:$N$15,MATCH($B$9,Dados_Evap!$A$2:$A$15,0),C28),0))} | G28: =IF(F28="","",F28/1000) | H28: =IF(D28="","",MAX(0,MIN($B$8,IFERROR(LOOKUP(2,1/($U$24:U27<>""),$U$24:U27),$B$11)))) | I28: {=IF(D28="","",IF(H28<=$B$16,INDEX(Aux_CAV!$B$2:$B$121,1),IF(H28>=$B$17,INDEX(Aux_CAV!$B$2:$B$121,$B$21),INDEX(Aux_CAV!$B$2:$B$121,AA28)+(H28-INDEX(Aux_CAV!$A$2:$A$121,AA28))*(INDEX(Aux_CAV!$B$2:$B$121,AA28+1)-INDEX(Aux_CAV!$B$2:$B$121,AA28))/(INDEX(Aux_CAV!$A$2:$A$121,AA28+1)-INDEX(Aux_CAV!$A$2:$A$121,AA28)))))} | J28: =IF(D28="","",$B$12) | K28: =IF(J28="","",J28*$B$15) | L28: =IF(D28="","",H28+E28-K28-G28*I28) | M28: {=IF(D28="","",IF(L28<=$B$16,INDEX(Aux_CAV!$B$2:$B$121,1),IF(L28>=$B$17,INDEX(Aux_CAV!$B$2:$B$121,$B$21),INDEX(Aux_CAV!$B$2:$B$121,AB28)+(L28-INDEX(Aux_CAV!$A$2:$A$121,AB28))*(INDEX(Aux_CAV!$B$2:$B$121,AB28+1)-INDEX(Aux_CAV!$B$2:$B$121,AB28))/(INDEX(Aux_CAV!$A$2:$A$121,AB28+1)-INDEX(Aux_CAV!$A$2:$A$121,AB28)))))} | N28: =IF(D28="","",(I28+M28)/2) | O28: =IF(D28="","",G28*N28) | P28: =IF(D28="","",H28+E28-K28-O28) | Q28: =IF(D28="","",IF(P28>=0,K28,MAX(0,K28+P28))) | R28: =IF(D28="","",Q28/$B$15) | S28: =IF(D28="","",MAX(0,J28-R28)) | T28: =IF(D28="","",MAX(0,Z28-$B$8)) | U28: =IF(D28="","",MAX(0,MIN($B$8,Z28))) | V28: =IF(D28="","",IF(S28>0.0000001,"Sim","Não")) | W28: =IF(D28="","",U28-(H28+E28-Q28-O28-T28)) | X28: =IF(W28="","",ABS(W28)) | Y28: =IF(U28="","",IF($B$8=0,0,U28/$B$8*100)) | Z28: =IF(D28="","",MAX(0,IF(P28>=0,P28,IF(K28+P28>=0,0,P28+K28)))) | AA28: =IF(D28="","",IF(H28<=$B$16,1,IF(H28>=$B$17,$B$21,MATCH(H28,Aux_CAV!$A$2:$A$121,1)))) | AB28: =IF(D28="","",IF(L28<=$B$16,1,IF(L28>=$B$17,$B$21,MATCH(L28,Aux_CAV!$A$2:$A$121,1)))) | AC28: =IF(D28="","",COUNT($D$24:D28))
A29: =IF(D29="","",DATE(B29,C29,1)) | B29: {=IF(D29="","",IFERROR(VALUE(INDEX(Vazoes_COLAR!$A$2:$A$200,INT((ROW()-24)/12)+1)),""))} | C29: =IF(D29="","",MOD(ROW()-24,12)+1) | D29: {=IF(ISBLANK(INDEX(Vazoes_COLAR!$B$2:$M$200,INT((ROW()-24)/12)+1,MOD(ROW()-24,12)+1)),"",IF(ISNUMBER(INDEX(Vazoes_COLAR!$B$2:$M$200,INT((ROW()-24)/12)+1,MOD(ROW()-24,12)+1)),INDEX(Vazoes_COLAR!$B$2:$M$200,INT((ROW()-24)/12)+1,MOD(ROW()-24,12)+1),IFERROR(NUMBERVALUE(INDEX(Vazoes_COLAR!$B$2:$M$200,INT((ROW()-24)/12)+1,MOD(ROW()-24,12)+1),",","."),"")))} | E29: =IF(D29="","",D29*$B$15) | F29: {=IF(D29="","",IFERROR(INDEX(Dados_Evap!$C$2:$N$15,MATCH($B$9,Dados_Evap!$A$2:$A$15,0),C29),0))} | G29: =IF(F29="","",F29/1000) | H29: =IF(D29="","",MAX(0,MIN($B$8,IFERROR(LOOKUP(2,1/($U$24:U28<>""),$U$24:U28),$B$11)))) | I29: {=IF(D29="","",IF(H29<=$B$16,INDEX(Aux_CAV!$B$2:$B$121,1),IF(H29>=$B$17,INDEX(Aux_CAV!$B$2:$B$121,$B$21),INDEX(Aux_CAV!$B$2:$B$121,AA29)+(H29-INDEX(Aux_CAV!$A$2:$A$121,AA29))*(INDEX(Aux_CAV!$B$2:$B$121,AA29+1)-INDEX(Aux_CAV!$B$2:$B$121,AA29))/(INDEX(Aux_CAV!$A$2:$A$121,AA29+1)-INDEX(Aux_CAV!$A$2:$A$121,AA29)))))} | J29: =IF(D29="","",$B$12) | K29: =IF(J29="","",J29*$B$15) | L29: =IF(D29="","",H29+E29-K29-G29*I29) | M29: {=IF(D29="","",IF(L29<=$B$16,INDEX(Aux_CAV!$B$2:$B$121,1),IF(L29>=$B$17,INDEX(Aux_CAV!$B$2:$B$121,$B$21),INDEX(Aux_CAV!$B$2:$B$121,AB29)+(L29-INDEX(Aux_CAV!$A$2:$A$121,AB29))*(INDEX(Aux_CAV!$B$2:$B$121,AB29+1)-INDEX(Aux_CAV!$B$2:$B$121,AB29))/(INDEX(Aux_CAV!$A$2:$A$121,AB29+1)-INDEX(Aux_CAV!$A$2:$A$121,AB29)))))} | N29: =IF(D29="","",(I29+M29)/2) | O29: =IF(D29="","",G29*N29) | P29: =IF(D29="","",H29+E29-K29-O29) | Q29: =IF(D29="","",IF(P29>=0,K29,MAX(0,K29+P29))) | R29: =IF(D29="","",Q29/$B$15) | S29: =IF(D29="","",MAX(0,J29-R29)) | T29: =IF(D29="","",MAX(0,Z29-$B$8)) | U29: =IF(D29="","",MAX(0,MIN($B$8,Z29))) | V29: =IF(D29="","",IF(S29>0.0000001,"Sim","Não")) | W29: =IF(D29="","",U29-(H29+E29-Q29-O29-T29)) | X29: =IF(W29="","",ABS(W29)) | Y29: =IF(U29="","",IF($B$8=0,0,U29/$B$8*100)) | Z29: =IF(D29="","",MAX(0,IF(P29>=0,P29,IF(K29+P29>=0,0,P29+K29)))) | AA29: =IF(D29="","",IF(H29<=$B$16,1,IF(H29>=$B$17,$B$21,MATCH(H29,Aux_CAV!$A$2:$A$121,1)))) | AB29: =IF(D29="","",IF(L29<=$B$16,1,IF(L29>=$B$17,$B$21,MATCH(L29,Aux_CAV!$A$2:$A$121,1)))) | AC29: =IF(D29="","",COUNT($D$24:D29))
A30: =IF(D30="","",DATE(B30,C30,1)) | B30: {=IF(D30="","",IFERROR(VALUE(INDEX(Vazoes_COLAR!$A$2:$A$200,INT((ROW()-24)/12)+1)),""))} | C30: =IF(D30="","",MOD(ROW()-24,12)+1) | D30: {=IF(ISBLANK(INDEX(Vazoes_COLAR!$B$2:$M$200,INT((ROW()-24)/12)+1,MOD(ROW()-24,12)+1)),"",IF(ISNUMBER(INDEX(Vazoes_COLAR!$B$2:$M$200,INT((ROW()-24)/12)+1,MOD(ROW()-24,12)+1)),INDEX(Vazoes_COLAR!$B$2:$M$200,INT((ROW()-24)/12)+1,MOD(ROW()-24,12)+1),IFERROR(NUMBERVALUE(INDEX(Vazoes_COLAR!$B$2:$M$200,INT((ROW()-24)/12)+1,MOD(ROW()-24,12)+1),",","."),"")))} | E30: =IF(D30="","",D30*$B$15) | F30: {=IF(D30="","",IFERROR(INDEX(Dados_Evap!$C$2:$N$15,MATCH($B$9,Dados_Evap!$A$2:$A$15,0),C30),0))} | G30: =IF(F30="","",F30/1000) | H30: =IF(D30="","",MAX(0,MIN($B$8,IFERROR(LOOKUP(2,1/($U$24:U29<>""),$U$24:U29),$B$11)))) | I30: {=IF(D30="","",IF(H30<=$B$16,INDEX(Aux_CAV!$B$2:$B$121,1),IF(H30>=$B$17,INDEX(Aux_CAV!$B$2:$B$121,$B$21),INDEX(Aux_CAV!$B$2:$B$121,AA30)+(H30-INDEX(Aux_CAV!$A$2:$A$121,AA30))*(INDEX(Aux_CAV!$B$2:$B$121,AA30+1)-INDEX(Aux_CAV!$B$2:$B$121,AA30))/(INDEX(Aux_CAV!$A$2:$A$121,AA30+1)-INDEX(Aux_CAV!$A$2:$A$121,AA30)))))} | J30: =IF(D30="","",$B$12) | K30: =IF(J30="","",J30*$B$15) | L30: =IF(D30="","",H30+E30-K30-G30*I30) | M30: {=IF(D30="","",IF(L30<=$B$16,INDEX(Aux_CAV!$B$2:$B$121,1),IF(L30>=$B$17,INDEX(Aux_CAV!$B$2:$B$121,$B$21),INDEX(Aux_CAV!$B$2:$B$121,AB30)+(L30-INDEX(Aux_CAV!$A$2:$A$121,AB30))*(INDEX(Aux_CAV!$B$2:$B$121,AB30+1)-INDEX(Aux_CAV!$B$2:$B$121,AB30))/(INDEX(Aux_CAV!$A$2:$A$121,AB30+1)-INDEX(Aux_CAV!$A$2:$A$121,AB30)))))} | N30: =IF(D30="","",(I30+M30)/2) | O30: =IF(D30="","",G30*N30) | P30: =IF(D30="","",H30+E30-K30-O30) | Q30: =IF(D30="","",IF(P30>=0,K30,MAX(0,K30+P30))) | R30: =IF(D30="","",Q30/$B$15) | S30: =IF(D30="","",MAX(0,J30-R30)) | T30: =IF(D30="","",MAX(0,Z30-$B$8)) | U30: =IF(D30="","",MAX(0,MIN($B$8,Z30))) | V30: =IF(D30="","",IF(S30>0.0000001,"Sim","Não")) | W30: =IF(D30="","",U30-(H30+E30-Q30-O30-T30)) | X30: =IF(W30="","",ABS(W30)) | Y30: =IF(U30="","",IF($B$8=0,0,U30/$B$8*100)) | Z30: =IF(D30="","",MAX(0,IF(P30>=0,P30,IF(K30+P30>=0,0,P30+K30)))) | AA30: =IF(D30="","",IF(H30<=$B$16,1,IF(H30>=$B$17,$B$21,MATCH(H30,Aux_CAV!$A$2:$A$121,1)))) | AB30: =IF(D30="","",IF(L30<=$B$16,1,IF(L30>=$B$17,$B$21,MATCH(L30,Aux_CAV!$A$2:$A$121,1)))) | AC30: =IF(D30="","",COUNT($D$24:D30))
A31: =IF(D31="","",DATE(B31,C31,1)) | B31: {=IF(D31="","",IFERROR(VALUE(INDEX(Vazoes_COLAR!$A$2:$A$200,INT((ROW()-24)/12)+1)),""))} | C31: =IF(D31="","",MOD(ROW()-24,12)+1) | D31: {=IF(ISBLANK(INDEX(Vazoes_COLAR!$B$2:$M$200,INT((ROW()-24)/12)+1,MOD(ROW()-24,12)+1)),"",IF(ISNUMBER(INDEX(Vazoes_COLAR!$B$2:$M$200,INT((ROW()-24)/12)+1,MOD(ROW()-24,12)+1)),INDEX(Vazoes_COLAR!$B$2:$M$200,INT((ROW()-24)/12)+1,MOD(ROW()-24,12)+1),IFERROR(NUMBERVALUE(INDEX(Vazoes_COLAR!$B$2:$M$200,INT((ROW()-24)/12)+1,MOD(ROW()-24,12)+1),",","."),"")))} | E31: =IF(D31="","",D31*$B$15) | F31: {=IF(D31="","",IFERROR(INDEX(Dados_Evap!$C$2:$N$15,MATCH($B$9,Dados_Evap!$A$2:$A$15,0),C31),0))} | G31: =IF(F31="","",F31/1000) | H31: =IF(D31="","",MAX(0,MIN($B$8,IFERROR(LOOKUP(2,1/($U$24:U30<>""),$U$24:U30),$B$11)))) | I31: {=IF(D31="","",IF(H31<=$B$16,INDEX(Aux_CAV!$B$2:$B$121,1),IF(H31>=$B$17,INDEX(Aux_CAV!$B$2:$B$121,$B$21),INDEX(Aux_CAV!$B$2:$B$121,AA31)+(H31-INDEX(Aux_CAV!$A$2:$A$121,AA31))*(INDEX(Aux_CAV!$B$2:$B$121,AA31+1)-INDEX(Aux_CAV!$B$2:$B$121,AA31))/(INDEX(Aux_CAV!$A$2:$A$121,AA31+1)-INDEX(Aux_CAV!$A$2:$A$121,AA31)))))} | J31: =IF(D31="","",$B$12) | K31: =IF(J31="","",J31*$B$15) | L31: =IF(D31="","",H31+E31-K31-G31*I31) | M31: {=IF(D31="","",IF(L31<=$B$16,INDEX(Aux_CAV!$B$2:$B$121,1),IF(L31>=$B$17,INDEX(Aux_CAV!$B$2:$B$121,$B$21),INDEX(Aux_CAV!$B$2:$B$121,AB31)+(L31-INDEX(Aux_CAV!$A$2:$A$121,AB31))*(INDEX(Aux_CAV!$B$2:$B$121,AB31+1)-INDEX(Aux_CAV!$B$2:$B$121,AB31))/(INDEX(Aux_CAV!$A$2:$A$121,AB31+1)-INDEX(Aux_CAV!$A$2:$A$121,AB31)))))} | N31: =IF(D31="","",(I31+M31)/2) | O31: =IF(D31="","",G31*N31) | P31: =IF(D31="","",H31+E31-K31-O31) | Q31: =IF(D31="","",IF(P31>=0,K31,MAX(0,K31+P31))) | R31: =IF(D31="","",Q31/$B$15) | S31: =IF(D31="","",MAX(0,J31-R31)) | T31: =IF(D31="","",MAX(0,Z31-$B$8)) | U31: =IF(D31="","",MAX(0,MIN($B$8,Z31))) | V31: =IF(D31="","",IF(S31>0.0000001,"Sim","Não")) | W31: =IF(D31="","",U31-(H31+E31-Q31-O31-T31)) | X31: =IF(W31="","",ABS(W31)) | Y31: =IF(U31="","",IF($B$8=0,0,U31/$B$8*100)) | Z31: =IF(D31="","",MAX(0,IF(P31>=0,P31,IF(K31+P31>=0,0,P31+K31)))) | AA31: =IF(D31="","",IF(H31<=$B$16,1,IF(H31>=$B$17,$B$21,MATCH(H31,Aux_CAV!$A$2:$A$121,1)))) | AB31: =IF(D31="","",IF(L31<=$B$16,1,IF(L31>=$B$17,$B$21,MATCH(L31,Aux_CAV!$A$2:$A$121,1)))) | AC31: =IF(D31="","",COUNT($D$24:D31))
A32: =IF(D32="","",DATE(B32,C32,1)) | B32: {=IF(D32="","",IFERROR(VALUE(INDEX(Vazoes_COLAR!$A$2:$A$200,INT((ROW()-24)/12)+1)),""))} | C32: =IF(D32="","",MOD(ROW()-24,12)+1) | D32: {=IF(ISBLANK(INDEX(Vazoes_COLAR!$B$2:$M$200,INT((ROW()-24)/12)+1,MOD(ROW()-24,12)+1)),"",IF(ISNUMBER(INDEX(Vazoes_COLAR!$B$2:$M$200,INT((ROW()-24)/12)+1,MOD(ROW()-24,12)+1)),INDEX(Vazoes_COLAR!$B$2:$M$200,INT((ROW()-24)/12)+1,MOD(ROW()-24,12)+1),IFERROR(NUMBERVALUE(INDEX(Vazoes_COLAR!$B$2:$M$200,INT((ROW()-24)/12)+1,MOD(ROW()-24,12)+1),",","."),"")))} | E32: =IF(D32="","",D32*$B$15) | F32: {=IF(D32="","",IFERROR(INDEX(Dados_Evap!$C$2:$N$15,MATCH($B$9,Dados_Evap!$A$2:$A$15,0),C32),0))} | G32: =IF(F32="","",F32/1000) | H32: =IF(D32="","",MAX(0,MIN($B$8,IFERROR(LOOKUP(2,1/($U$24:U31<>""),$U$24:U31),$B$11)))) | I32: {=IF(D32="","",IF(H32<=$B$16,INDEX(Aux_CAV!$B$2:$B$121,1),IF(H32>=$B$17,INDEX(Aux_CAV!$B$2:$B$121,$B$21),INDEX(Aux_CAV!$B$2:$B$121,AA32)+(H32-INDEX(Aux_CAV!$A$2:$A$121,AA32))*(INDEX(Aux_CAV!$B$2:$B$121,AA32+1)-INDEX(Aux_CAV!$B$2:$B$121,AA32))/(INDEX(Aux_CAV!$A$2:$A$121,AA32+1)-INDEX(Aux_CAV!$A$2:$A$121,AA32)))))} | J32: =IF(D32="","",$B$12) | K32: =IF(J32="","",J32*$B$15) | L32: =IF(D32="","",H32+E32-K32-G32*I32) | M32: {=IF(D32="","",IF(L32<=$B$16,INDEX(Aux_CAV!$B$2:$B$121,1),IF(L32>=$B$17,INDEX(Aux_CAV!$B$2:$B$121,$B$21),INDEX(Aux_CAV!$B$2:$B$121,AB32)+(L32-INDEX(Aux_CAV!$A$2:$A$121,AB32))*(INDEX(Aux_CAV!$B$2:$B$121,AB32+1)-INDEX(Aux_CAV!$B$2:$B$121,AB32))/(INDEX(Aux_CAV!$A$2:$A$121,AB32+1)-INDEX(Aux_CAV!$A$2:$A$121,AB32)))))} | N32: =IF(D32="","",(I32+M32)/2) | O32: =IF(D32="","",G32*N32) | P32: =IF(D32="","",H32+E32-K32-O32) | Q32: =IF(D32="","",IF(P32>=0,K32,MAX(0,K32+P32))) | R32: =IF(D32="","",Q32/$B$15) | S32: =IF(D32="","",MAX(0,J32-R32)) | T32: =IF(D32="","",MAX(0,Z32-$B$8)) | U32: =IF(D32="","",MAX(0,MIN($B$8,Z32))) | V32: =IF(D32="","",IF(S32>0.0000001,"Sim","Não")) | W32: =IF(D32="","",U32-(H32+E32-Q32-O32-T32)) | X32: =IF(W32="","",ABS(W32)) | Y32: =IF(U32="","",IF($B$8=0,0,U32/$B$8*100)) | Z32: =IF(D32="","",MAX(0,IF(P32>=0,P32,IF(K32+P32>=0,0,P32+K32)))) | AA32: =IF(D32="","",IF(H32<=$B$16,1,IF(H32>=$B$17,$B$21,MATCH(H32,Aux_CAV!$A$2:$A$121,1)))) | AB32: =IF(D32="","",IF(L32<=$B$16,1,IF(L32>=$B$17,$B$21,MATCH(L32,Aux_CAV!$A$2:$A$121,1)))) | AC32: =IF(D32="","",COUNT($D$24:D32))
A33: =IF(D33="","",DATE(B33,C33,1)) | B33: {=IF(D33="","",IFERROR(VALUE(INDEX(Vazoes_COLAR!$A$2:$A$200,INT((ROW()-24)/12)+1)),""))} | C33: =IF(D33="","",MOD(ROW()-24,12)+1) | D33: {=IF(ISBLANK(INDEX(Vazoes_COLAR!$B$2:$M$200,INT((ROW()-24)/12)+1,MOD(ROW()-24,12)+1)),"",IF(ISNUMBER(INDEX(Vazoes_COLAR!$B$2:$M$200,INT((ROW()-24)/12)+1,MOD(ROW()-24,12)+1)),INDEX(Vazoes_COLAR!$B$2:$M$200,INT((ROW()-24)/12)+1,MOD(ROW()-24,12)+1),IFERROR(NUMBERVALUE(INDEX(Vazoes_COLAR!$B$2:$M$200,INT((ROW()-24)/12)+1,MOD(ROW()-24,12)+1),",","."),"")))} | E33: =IF(D33="","",D33*$B$15) | F33: {=IF(D33="","",IFERROR(INDEX(Dados_Evap!$C$2:$N$15,MATCH($B$9,Dados_Evap!$A$2:$A$15,0),C33),0))} | G33: =IF(F33="","",F33/1000) | H33: =IF(D33="","",MAX(0,MIN($B$8,IFERROR(LOOKUP(2,1/($U$24:U32<>""),$U$24:U32),$B$11)))) | I33: {=IF(D33="","",IF(H33<=$B$16,INDEX(Aux_CAV!$B$2:$B$121,1),IF(H33>=$B$17,INDEX(Aux_CAV!$B$2:$B$121,$B$21),INDEX(Aux_CAV!$B$2:$B$121,AA33)+(H33-INDEX(Aux_CAV!$A$2:$A$121,AA33))*(INDEX(Aux_CAV!$B$2:$B$121,AA33+1)-INDEX(Aux_CAV!$B$2:$B$121,AA33))/(INDEX(Aux_CAV!$A$2:$A$121,AA33+1)-INDEX(Aux_CAV!$A$2:$A$121,AA33)))))} | J33: =IF(D33="","",$B$12) | K33: =IF(J33="","",J33*$B$15) | L33: =IF(D33="","",H33+E33-K33-G33*I33) | M33: {=IF(D33="","",IF(L33<=$B$16,INDEX(Aux_CAV!$B$2:$B$121,1),IF(L33>=$B$17,INDEX(Aux_CAV!$B$2:$B$121,$B$21),INDEX(Aux_CAV!$B$2:$B$121,AB33)+(L33-INDEX(Aux_CAV!$A$2:$A$121,AB33))*(INDEX(Aux_CAV!$B$2:$B$121,AB33+1)-INDEX(Aux_CAV!$B$2:$B$121,AB33))/(INDEX(Aux_CAV!$A$2:$A$121,AB33+1)-INDEX(Aux_CAV!$A$2:$A$121,AB33)))))} | N33: =IF(D33="","",(I33+M33)/2) | O33: =IF(D33="","",G33*N33) | P33: =IF(D33="","",H33+E33-K33-O33) | Q33: =IF(D33="","",IF(P33>=0,K33,MAX(0,K33+P33))) | R33: =IF(D33="","",Q33/$B$15) | S33: =IF(D33="","",MAX(0,J33-R33)) | T33: =IF(D33="","",MAX(0,Z33-$B$8)) | U33: =IF(D33="","",MAX(0,MIN($B$8,Z33))) | V33: =IF(D33="","",IF(S33>0.0000001,"Sim","Não")) | W33: =IF(D33="","",U33-(H33+E33-Q33-O33-T33)) | X33: =IF(W33="","",ABS(W33)) | Y33: =IF(U33="","",IF($B$8=0,0,U33/$B$8*100)) | Z33: =IF(D33="","",MAX(0,IF(P33>=0,P33,IF(K33+P33>=0,0,P33+K33)))) | AA33: =IF(D33="","",IF(H33<=$B$16,1,IF(H33>=$B$17,$B$21,MATCH(H33,Aux_CAV!$A$2:$A$121,1)))) | AB33: =IF(D33="","",IF(L33<=$B$16,1,IF(L33>=$B$17,$B$21,MATCH(L33,Aux_CAV!$A$2:$A$121,1)))) | AC33: =IF(D33="","",COUNT($D$24:D33))
A34: =IF(D34="","",DATE(B34,C34,1)) -> 3958 | B34: {=IF(D34="","",IFERROR(VALUE(INDEX(Vazoes_COLAR!$A$2:$A$200,INT((ROW()-24)/12)+1)),""))} -> 1910 | C34: =IF(D34="","",MOD(ROW()-24,12)+1) -> 11 | D34: {=IF(ISBLANK(INDEX(Vazoes_COLAR!$B$2:$M$200,INT((ROW()-24)/12)+1,MOD(ROW()-24,12)+1)),"",IF(ISNUMBER(INDEX(Vazoes_COLAR!$B$2:$M$200,INT((ROW()-24)/12)+1,MOD(ROW()-24,12)+1)),INDEX(Vazoes_COLAR!$B$2:$M$200,INT((ROW()-24)/12)+1,MOD(ROW()-24,12)+1),IFERROR(NUMBERVALUE(INDEX(Vazoes_COLAR!$B$2:$M$200,INT((ROW()-24)/12)+1,MOD(ROW()-24,12)+1),",","."),"")))} -> 0 | E34: =IF(D34="","",D34*$B$15) -> 0 | F34: {=IF(D34="","",IFERROR(INDEX(Dados_Evap!$C$2:$N$15,MATCH($B$9,Dados_Evap!$A$2:$A$15,0),C34),0))} -> 225.9 | G34: =IF(F34="","",F34/1000) -> 0.2259 | H34: =IF(D34="","",MAX(0,MIN($B$8,IFERROR(LOOKUP(2,1/($U$24:U33<>""),$U$24:U33),$B$11)))) -> 10.65 | I34: {=IF(D34="","",IF(H34<=$B$16,INDEX(Aux_CAV!$B$2:$B$121,1),IF(H34>=$B$17,INDEX(Aux_CAV!$B$2:$B$121,$B$21),INDEX(Aux_CAV!$B$2:$B$121,AA34)+(H34-INDEX(Aux_CAV!$A$2:$A$121,AA34))*(INDEX(Aux_CAV!$B$2:$B$121,AA34+1)-INDEX(Aux_CAV!$B$2:$B$121,AA34))/(INDEX(Aux_CAV!$A$2:$A$121,AA34+1)-INDEX(Aux_CAV!$A$2:$A$121,AA34)))))} -> 0.95108407 | J34: =IF(D34="","",$B$12) -> 0.5 | K34: =IF(J34="","",J34*$B$15) -> 1.296 | L34: =IF(D34="","",H34+E34-K34-G34*I34) -> 9.1391501 | M34: {=IF(D34="","",IF(L34<=$B$16,INDEX(Aux_CAV!$B$2:$B$121,1),IF(L34>=$B$17,INDEX(Aux_CAV!$B$2:$B$121,$B$21),INDEX(Aux_CAV!$B$2:$B$121,AB34)+(L34-INDEX(Aux_CAV!$A$2:$A$121,AB34))*(INDEX(Aux_CAV!$B$2:$B$121,AB34+1)-INDEX(Aux_CAV!$B$2:$B$121,AB34))/(INDEX(Aux_CAV!$A$2:$A$121,AB34+1)-INDEX(Aux_CAV!$A$2:$A$121,AB34)))))} -> 0.90094525 | N34: =IF(D34="","",(I34+M34)/2) -> 0.92601466 | O34: =IF(D34="","",G34*N34) -> 0.20918671 | P34: =IF(D34="","",H34+E34-K34-O34) -> 9.1448133 | Q34: =IF(D34="","",IF(P34>=0,K34,MAX(0,K34+P34))) -> 1.296 | R34: =IF(D34="","",Q34/$B$15) -> 0.5 | S34: =IF(D34="","",MAX(0,J34-R34)) -> 0 | T34: =IF(D34="","",MAX(0,Z34-$B$8)) -> 0 | U34: =IF(D34="","",MAX(0,MIN($B$8,Z34))) -> 9.1448133 | V34: =IF(D34="","",IF(S34>0.0000001,"Sim","Não")) -> Não | W34: =IF(D34="","",U34-(H34+E34-Q34-O34-T34)) -> 0 | X34: =IF(W34="","",ABS(W34)) -> 0 | Y34: =IF(U34="","",IF($B$8=0,0,U34/$B$8*100)) -> 42.933396 | Z34: =IF(D34="","",MAX(0,IF(P34>=0,P34,IF(K34+P34>=0,0,P34+K34)))) -> 9.1448133 | AA34: =IF(D34="","",IF(H34<=$B$16,1,IF(H34>=$B$17,$B$21,MATCH(H34,Aux_CAV!$A$2:$A$121,1)))) -> 5 | AB34: =IF(D34="","",IF(L34<=$B$16,1,IF(L34>=$B$17,$B$21,MATCH(L34,Aux_CAV!$A$2:$A$121,1)))) -> 5 | AC34: =IF(D34="","",COUNT($D$24:D34)) -> 1
A35: =IF(D35="","",DATE(B35,C35,1)) -> 3988 | B35: {=IF(D35="","",IFERROR(VALUE(INDEX(Vazoes_COLAR!$A$2:$A$200,INT((ROW()-24)/12)+1)),""))} -> 1910 | C35: =IF(D35="","",MOD(ROW()-24,12)+1) -> 12 | D35: {=IF(ISBLANK(INDEX(Vazoes_COLAR!$B$2:$M$200,INT((ROW()-24)/12)+1,MOD(ROW()-24,12)+1)),"",IF(ISNUMBER(INDEX(Vazoes_COLAR!$B$2:$M$200,INT((ROW()-24)/12)+1,MOD(ROW()-24,12)+1)),INDEX(Vazoes_COLAR!$B$2:$M$200,INT((ROW()-24)/12)+1,MOD(ROW()-24,12)+1),IFERROR(NUMBERVALUE(INDEX(Vazoes_COLAR!$B$2:$M$200,INT((ROW()-24)/12)+1,MOD(ROW()-24,12)+1),",","."),"")))} -> 0 | E35: =IF(D35="","",D35*$B$15) -> 0 | F35: {=IF(D35="","",IFERROR(INDEX(Dados_Evap!$C$2:$N$15,MATCH($B$9,Dados_Evap!$A$2:$A$15,0),C35),0))} -> 206 | G35: =IF(F35="","",F35/1000) -> 0.206 | H35: =IF(D35="","",MAX(0,MIN($B$8,IFERROR(LOOKUP(2,1/($U$24:U34<>""),$U$24:U34),$B$11)))) -> 10.65 | I35: {=IF(D35="","",IF(H35<=$B$16,INDEX(Aux_CAV!$B$2:$B$121,1),IF(H35>=$B$17,INDEX(Aux_CAV!$B$2:$B$121,$B$21),INDEX(Aux_CAV!$B$2:$B$121,AA35)+(H35-INDEX(Aux_CAV!$A$2:$A$121,AA35))*(INDEX(Aux_CAV!$B$2:$B$121,AA35+1)-INDEX(Aux_CAV!$B$2:$B$121,AA35))/(INDEX(Aux_CAV!$A$2:$A$121,AA35+1)-INDEX(Aux_CAV!$A$2:$A$121,AA35)))))} -> 0.95108407 | J35: =IF(D35="","",$B$12) -> 0.5 | K35: =IF(J35="","",J35*$B$15) -> 1.296 | L35: =IF(D35="","",H35+E35-K35-G35*I35) -> 9.1580767 | M35: {=IF(D35="","",IF(L35<=$B$16,INDEX(Aux_CAV!$B$2:$B$121,1),IF(L35>=$B$17,INDEX(Aux_CAV!$B$2:$B$121,$B$21),INDEX(Aux_CAV!$B$2:$B$121,AB35)+(L35-INDEX(Aux_CAV!$A$2:$A$121,AB35))*(INDEX(Aux_CAV!$B$2:$B$121,AB35+1)-INDEX(Aux_CAV!$B$2:$B$121,AB35))/(INDEX(Aux_CAV!$A$2:$A$121,AB35+1)-INDEX(Aux_CAV!$A$2:$A$121,AB35)))))} -> 0.90157334 | N35: =IF(D35="","",(I35+M35)/2) -> 0.92632871 | O35: =IF(D35="","",G35*N35) -> 0.19082371 | P35: =IF(D35="","",H35+E35-K35-O35) -> 9.1631763 | Q35: =IF(D35="","",IF(P35>=0,K35,MAX(0,K35+P35))) -> 1.296 | R35: =IF(D35="","",Q35/$B$15) -> 0.5 | S35: =IF(D35="","",MAX(0,J35-R35)) -> 0 | T35: =IF(D35="","",MAX(0,Z35-$B$8)) -> 0 | U35: =IF(D35="","",MAX(0,MIN($B$8,Z35))) -> 9.1631763 | V35: =IF(D35="","",IF(S35>0.0000001,"Sim","Não")) -> Não | W35: =IF(D35="","",U35-(H35+E35-Q35-O35-T35)) -> 0 | X35: =IF(W35="","",ABS(W35)) -> 0 | Y35: =IF(U35="","",IF($B$8=0,0,U35/$B$8*100)) -> 43.019607 | Z35: =IF(D35="","",MAX(0,IF(P35>=0,P35,IF(K35+P35>=0,0,P35+K35)))) -> 9.1631763 | AA35: =IF(D35="","",IF(H35<=$B$16,1,IF(H35>=$B$17,$B$21,MATCH(H35,Aux_CAV!$A$2:$A$121,1)))) -> 5 | AB35: =IF(D35="","",IF(L35<=$B$16,1,IF(L35>=$B$17,$B$21,MATCH(L35,Aux_CAV!$A$2:$A$121,1)))) -> 5 | AC35: =IF(D35="","",COUNT($D$24:D35)) -> 2
A36: =IF(D36="","",DATE(B36,C36,1)) | B36: {=IF(D36="","",IFERROR(VALUE(INDEX(Vazoes_COLAR!$A$2:$A$200,INT((ROW()-24)/12)+1)),""))} | C36: =IF(D36="","",MOD(ROW()-24,12)+1) | D36: {=IF(ISBLANK(INDEX(Vazoes_COLAR!$B$2:$M$200,INT((ROW()-24)/12)+1,MOD(ROW()-24,12)+1)),"",IF(ISNUMBER(INDEX(Vazoes_COLAR!$B$2:$M$200,INT((ROW()-24)/12)+1,MOD(ROW()-24,12)+1)),INDEX(Vazoes_COLAR!$B$2:$M$200,INT((ROW()-24)/12)+1,MOD(ROW()-24,12)+1),IFERROR(NUMBERVALUE(INDEX(Vazoes_COLAR!$B$2:$M$200,INT((ROW()-24)/12)+1,MOD(ROW()-24,12)+1),",","."),"")))} | E36: =IF(D36="","",D36*$B$15) | F36: {=IF(D36="","",IFERROR(INDEX(Dados_Evap!$C$2:$N$15,MATCH($B$9,Dados_Evap!$A$2:$A$15,0),C36),0))} | G36: =IF(F36="","",F36/1000) | H36: =IF(D36="","",MAX(0,MIN($B$8,IFERROR(LOOKUP(2,1/($U$24:U35<>""),$U$24:U35),$B$11)))) | I36: {=IF(D36="","",IF(H36<=$B$16,INDEX(Aux_CAV!$B$2:$B$121,1),IF(H36>=$B$17,INDEX(Aux_CAV!$B$2:$B$121,$B$21),INDEX(Aux_CAV!$B$2:$B$121,AA36)+(H36-INDEX(Aux_CAV!$A$2:$A$121,AA36))*(INDEX(Aux_CAV!$B$2:$B$121,AA36+1)-INDEX(Aux_CAV!$B$2:$B$121,AA36))/(INDEX(Aux_CAV!$A$2:$A$121,AA36+1)-INDEX(Aux_CAV!$A$2:$A$121,AA36)))))} | J36: =IF(D36="","",$B$12) | K36: =IF(J36="","",J36*$B$15) | L36: =IF(D36="","",H36+E36-K36-G36*I36) | M36: {=IF(D36="","",IF(L36<=$B$16,INDEX(Aux_CAV!$B$2:$B$121,1),IF(L36>=$B$17,INDEX(Aux_CAV!$B$2:$B$121,$B$21),INDEX(Aux_CAV!$B$2:$B$121,AB36)+(L36-INDEX(Aux_CAV!$A$2:$A$121,AB36))*(INDEX(Aux_CAV!$B$2:$B$121,AB36+1)-INDEX(Aux_CAV!$B$2:$B$121,AB36))/(INDEX(Aux_CAV!$A$2:$A$121,AB36+1)-INDEX(Aux_CAV!$A$2:$A$121,AB36)))))} | N36: =IF(D36="","",(I36+M36)/2) | O36: =IF(D36="","",G36*N36) | P36: =IF(D36="","",H36+E36-K36-O36) | Q36: =IF(D36="","",IF(P36>=0,K36,MAX(0,K36+P36))) | R36: =IF(D36="","",Q36/$B$15) | S36: =IF(D36="","",MAX(0,J36-R36)) | T36: =IF(D36="","",MAX(0,Z36-$B$8)) | U36: =IF(D36="","",MAX(0,MIN($B$8,Z36))) | V36: =IF(D36="","",IF(S36>0.0000001,"Sim","Não")) | W36: =IF(D36="","",U36-(H36+E36-Q36-O36-T36)) | X36: =IF(W36="","",ABS(W36)) | Y36: =IF(U36="","",IF($B$8=0,0,U36/$B$8*100)) | Z36: =IF(D36="","",MAX(0,IF(P36>=0,P36,IF(K36+P36>=0,0,P36+K36)))) | AA36: =IF(D36="","",IF(H36<=$B$16,1,IF(H36>=$B$17,$B$21,MATCH(H36,Aux_CAV!$A$2:$A$121,1)))) | AB36: =IF(D36="","",IF(L36<=$B$16,1,IF(L36>=$B$17,$B$21,MATCH(L36,Aux_CAV!$A$2:$A$121,1)))) | AC36: =IF(D36="","",COUNT($D$24:D36))
... A1367: =IF(D1367="","",DATE(B1367,C1367,1)) | B1367: {=IF(D1367="","",IFERROR(VALUE(INDEX(Vazoes_COLAR!$A$2:$A$200,INT((ROW()-24)/12)+1)),""))} | C1367: =IF(D1367="","",MOD(ROW()-24,12)+1) | D1367: {=IF(ISBLANK(INDEX(Vazoes_COLAR!$B$2:$M$200,INT((ROW()-24)/12)+1,MOD(ROW()-24,12)+1)),"",IF(ISNUMBER(INDEX(Vazoes_COLAR!$B$2:$M$200,INT((ROW()-24)/12)+1,MOD(ROW()-24,12)+1)),INDEX(Vazoes_COLAR!$B$2:$M$200,INT((ROW()-24)/12)+1,MOD(ROW()-24,12)+1),IFERROR(NUMBERVALUE(INDEX(Vazoes_COLAR!$B$2:$M$200,INT((ROW()-24)/12)+1,MOD(ROW()-24,12)+1),",","."),"")))} | E1367: =IF(D1367="","",D1367*$B$15) | F1367: {=IF(D1367="","",IFERROR(INDEX(Dados_Evap!$C$2:$N$15,MATCH($B$9,Dados_Evap!$A$2:$A$15,0),C1367),0))} | G1367: =IF(F1367="","",F1367/1000) | H1367: =IF(D1367="","",MAX(0,MIN($B$8,IFERROR(LOOKUP(2,1/($U$24:U1366<>""),$U$24:U1366),$B$11)))) | I1367: {=IF(D1367="","",IF(H1367<=$B$16,INDEX(Aux_CAV!$B$2:$B$121,1),IF(H1367>=$B$17,INDEX(Aux_CAV!$B$2:$B$121,$B$21),INDEX(Aux_CAV!$B$2:$B$121,AA1367)+(H1367-INDEX(Aux_CAV!$A$2:$A$121,AA1367))*(INDEX(Aux_CAV!$B$2:$B$121,AA1367+1)-INDEX(Aux_CAV!$B$2:$B$121,AA1367))/(INDEX(Aux_CAV!$A$2:$A$121,AA1367+1)-INDEX(Aux_CAV!$A$2:$A$121,AA1367)))))} | J1367: =IF(D1367="","",$B$12) | K1367: =IF(J1367="","",J1367*$B$15) | L1367: =IF(D1367="","",H1367+E1367-K1367-G1367*I1367) | M1367: {=IF(D1367="","",IF(L1367<=$B$16,INDEX(Aux_CAV!$B$2:$B$121,1),IF(L1367>=$B$17,INDEX(Aux_CAV!$B$2:$B$121,$B$21),INDEX(Aux_CAV!$B$2:$B$121,AB1367)+(L1367-INDEX(Aux_CAV!$A$2:$A$121,AB1367))*(INDEX(Aux_CAV!$B$2:$B$121,AB1367+1)-INDEX(Aux_CAV!$B$2:$B$121,AB1367))/(INDEX(Aux_CAV!$A$2:$A$121,AB1367+1)-INDEX(Aux_CAV!$A$2:$A$121,AB1367)))))} | N1367: =IF(D1367="","",(I1367+M1367)/2) | O1367: =IF(D1367="","",G1367*N1367) | P1367: =IF(D1367="","",H1367+E1367-K1367-O1367) | Q1367: =IF(D1367="","",IF(P1367>=0,K1367,MAX(0,K1367+P1367))) | R1367: =IF(D1367="","",Q1367/$B$15) | S1367: =IF(D1367="","",MAX(0,J1367-R1367)) | T1367: =IF(D1367="","",MAX(0,Z1367-$B$8)) | U1367: =IF(D1367="","",MAX(0,MIN($B$8,Z1367))) | V1367: =IF(D1367="","",IF(S1367>0.0000001,"Sim","Não")) | W1367: =IF(D1367="","",U1367-(H1367+E1367-Q1367-O1367-T1367)) | X1367: =IF(W1367="","",ABS(W1367)) | Y1367: =IF(U1367="","",IF($B$8=0,0,U1367/$B$8*100)) | Z1367: =IF(D1367="","",MAX(0,IF(P1367>=0,P1367,IF(K1367+P1367>=0,0,P1367+K1367)))) | AA1367: =IF(D1367="","",IF(H1367<=$B$16,1,IF(H1367>=$B$17,$B$21,MATCH(H1367,Aux_CAV!$A$2:$A$121,1)))) | AB1367: =IF(D1367="","",IF(L1367<=$B$16,1,IF(L1367>=$B$17,$B$21,MATCH(L1367,Aux_CAV!$A$2:$A$121,1)))) | AC1367: =IF(D1367="","",COUNT($D$24:D1367))

Sheet Vazoes_COLAR
A1: 0 | B1: JAN | C1: FEV | D1: MAR | E1: ABR | F1: MAI | G1: JUN | H1: JUL | I1: AGO | J1: SET | K1: OUT | L1: NOV | M1: DEZ | O1: COMO USAR
A2: 1910 | L2: 0 | M2: 0 | O2: Série histórica: 1910 a 2021. Cole as vazões em B2:M113 ou cole a tabela completa em A1:M113. Meses vazios antes da primeira vazão são ignorados automaticamente. Use vírgula decimal normalmente.
A3: 1911
A4: 1912
A5: 1913
A6: 1914
A7: 1915
A8: 1916
A9: 1917
A10: 1918
A11: 1919
A12: 1920
A13: 1921
A14: 1922
... A113: 2021

Sheet Amostra_12_meses
A1: AMOSTRA DE 12 MESES PARA O PROTOCOLO DE VERIFICAÇÃO
A3: Escolha o ano em B5. Se o primeiro ano tiver apenas parte dos meses, somente os meses com dados aparecerão. P, R e T continuam opcionais para comparação com as saídas do simulador.
A5: Ano do relatório | B5: 1910 | D5: Opcional: cole nas colunas amarelas os resultados mensais exportados do simulador. As colunas adjacentes calculam as diferenças.
A7: Mês | B7: Data | C7: Q (m³/s) | D7: Afluência (hm³) | E7: Arm. inicial (hm³) | F7: Evap. (mm) | G7: Área média (km²) | H7: Evap. (hm³) | I7: Dem. sol. (m³/s) | J7: Dem. atend. (m³/s) | K7: Déficit (m³/s) | L7: Vertimento (hm³) | M7: Arm. final (hm³) | N7: Falha | O7: Resíduo ε (hm³) | P7: Vol. final SIM (hm³) | Q7: Dif. volume (hm³) | R7: Evap. SIM (hm³) | S7: Dif. evap. (hm³) | T7: Vert. SIM (hm³) | U7: Dif. vert. (hm³)
A8: JAN | B8: =DATE($B$5,1,1) -> 3654 | C8: {=IFERROR(INDEX(Verificacao!$D$24:$D$1367,MATCH($B8,Verificacao!$A$24:$A$1367,0)),"")} | D8: {=IFERROR(INDEX(Verificacao!$E$24:$E$1367,MATCH($B8,Verificacao!$A$24:$A$1367,0)),"")} | E8: {=IFERROR(INDEX(Verificacao!$H$24:$H$1367,MATCH($B8,Verificacao!$A$24:$A$1367,0)),"")} | F8: {=IFERROR(INDEX(Verificacao!$F$24:$F$1367,MATCH($B8,Verificacao!$A$24:$A$1367,0)),"")} | G8: {=IFERROR(INDEX(Verificacao!$N$24:$N$1367,MATCH($B8,Verificacao!$A$24:$A$1367,0)),"")} | H8: {=IFERROR(INDEX(Verificacao!$O$24:$O$1367,MATCH($B8,Verificacao!$A$24:$A$1367,0)),"")} | I8: {=IFERROR(INDEX(Verificacao!$J$24:$J$1367,MATCH($B8,Verificacao!$A$24:$A$1367,0)),"")} | J8: {=IFERROR(INDEX(Verificacao!$R$24:$R$1367,MATCH($B8,Verificacao!$A$24:$A$1367,0)),"")} | K8: {=IFERROR(INDEX(Verificacao!$S$24:$S$1367,MATCH($B8,Verificacao!$A$24:$A$1367,0)),"")} | L8: {=IFERROR(INDEX(Verificacao!$T$24:$T$1367,MATCH($B8,Verificacao!$A$24:$A$1367,0)),"")} | M8: {=IFERROR(INDEX(Verificacao!$U$24:$U$1367,MATCH($B8,Verificacao!$A$24:$A$1367,0)),"")} | N8: {=IFERROR(INDEX(Verificacao!$V$24:$V$1367,MATCH($B8,Verificacao!$A$24:$A$1367,0)),"")} | O8: {=IFERROR(INDEX(Verificacao!$W$24:$W$1367,MATCH($B8,Verificacao!$A$24:$A$1367,0)),"")} | Q8: =IF(OR(P8="",M8=""),"",P8-M8) | S8: =IF(OR(R8="",H8=""),"",R8-H8) | U8: =IF(OR(T8="",L8=""),"",T8-L8)
A9: FEV | B9: =DATE($B$5,2,1) -> 3685 | C9: {=IFERROR(INDEX(Verificacao!$D$24:$D$1367,MATCH($B9,Verificacao!$A$24:$A$1367,0)),"")} | D9: {=IFERROR(INDEX(Verificacao!$E$24:$E$1367,MATCH($B9,Verificacao!$A$24:$A$1367,0)),"")} | E9: {=IFERROR(INDEX(Verificacao!$H$24:$H$1367,MATCH($B9,Verificacao!$A$24:$A$1367,0)),"")} | F9: {=IFERROR(INDEX(Verificacao!$F$24:$F$1367,MATCH($B9,Verificacao!$A$24:$A$1367,0)),"")} | G9: {=IFERROR(INDEX(Verificacao!$N$24:$N$1367,MATCH($B9,Verificacao!$A$24:$A$1367,0)),"")} | H9: {=IFERROR(INDEX(Verificacao!$O$24:$O$1367,MATCH($B9,Verificacao!$A$24:$A$1367,0)),"")} | I9: {=IFERROR(INDEX(Verificacao!$J$24:$J$1367,MATCH($B9,Verificacao!$A$24:$A$1367,0)),"")} | J9: {=IFERROR(INDEX(Verificacao!$R$24:$R$1367,MATCH($B9,Verificacao!$A$24:$A$1367,0)),"")} | K9: {=IFERROR(INDEX(Verificacao!$S$24:$S$1367,MATCH($B9,Verificacao!$A$24:$A$1367,0)),"")} | L9: {=IFERROR(INDEX(Verificacao!$T$24:$T$1367,MATCH($B9,Verificacao!$A$24:$A$1367,0)),"")} | M9: {=IFERROR(INDEX(Verificacao!$U$24:$U$1367,MATCH($B9,Verificacao!$A$24:$A$1367,0)),"")} | N9: {=IFERROR(INDEX(Verificacao!$V$24:$V$1367,MATCH($B9,Verificacao!$A$24:$A$1367,0)),"")} | O9: {=IFERROR(INDEX(Verificacao!$W$24:$W$1367,MATCH($B9,Verificacao!$A$24:$A$1367,0)),"")} | Q9: =IF(OR(P9="",M9=""),"",P9-M9) | S9: =IF(OR(R9="",H9=""),"",R9-H9) | U9: =IF(OR(T9="",L9=""),"",T9-L9)
A10: MAR | B10: =DATE($B$5,3,1) -> 3713 | C10: {=IFERROR(INDEX(Verificacao!$D$24:$D$1367,MATCH($B10,Verificacao!$A$24:$A$1367,0)),"")} | D10: {=IFERROR(INDEX(Verificacao!$E$24:$E$1367,MATCH($B10,Verificacao!$A$24:$A$1367,0)),"")} | E10: {=IFERROR(INDEX(Verificacao!$H$24:$H$1367,MATCH($B10,Verificacao!$A$24:$A$1367,0)),"")} | F10: {=IFERROR(INDEX(Verificacao!$F$24:$F$1367,MATCH($B10,Verificacao!$A$24:$A$1367,0)),"")} | G10: {=IFERROR(INDEX(Verificacao!$N$24:$N$1367,MATCH($B10,Verificacao!$A$24:$A$1367,0)),"")} | H10: {=IFERROR(INDEX(Verificacao!$O$24:$O$1367,MATCH($B10,Verificacao!$A$24:$A$1367,0)),"")} | I10: {=IFERROR(INDEX(Verificacao!$J$24:$J$1367,MATCH($B10,Verificacao!$A$24:$A$1367,0)),"")} | J10: {=IFERROR(INDEX(Verificacao!$R$24:$R$1367,MATCH($B10,Verificacao!$A$24:$A$1367,0)),"")} | K10: {=IFERROR(INDEX(Verificacao!$S$24:$S$1367,MATCH($B10,Verificacao!$A$24:$A$1367,0)),"")} | L10: {=IFERROR(INDEX(Verificacao!$T$24:$T$1367,MATCH($B10,Verificacao!$A$24:$A$1367,0)),"")} | M10: {=IFERROR(INDEX(Verificacao!$U$24:$U$1367,MATCH($B10,Verificacao!$A$24:$A$1367,0)),"")} | N10: {=IFERROR(INDEX(Verificacao!$V$24:$V$1367,MATCH($B10,Verificacao!$A$24:$A$1367,0)),"")} | O10: {=IFERROR(INDEX(Verificacao!$W$24:$W$1367,MATCH($B10,Verificacao!$A$24:$A$1367,0)),"")} | Q10: =IF(OR(P10="",M10=""),"",P10-M10) | S10: =IF(OR(R10="",H10=""),"",R10-H10) | U10: =IF(OR(T10="",L10=""),"",T10-L10)
A11: ABR | B11: =DATE($B$5,4,1) -> 3744 | C11: {=IFERROR(INDEX(Verificacao!$D$24:$D$1367,MATCH($B11,Verificacao!$A$24:$A$1367,0)),"")} | D11: {=IFERROR(INDEX(Verificacao!$E$24:$E$1367,MATCH($B11,Verificacao!$A$24:$A$1367,0)),"")} | E11: {=IFERROR(INDEX(Verificacao!$H$24:$H$1367,MATCH($B11,Verificacao!$A$24:$A$1367,0)),"")} | F11: {=IFERROR(INDEX(Verificacao!$F$24:$F$1367,MATCH($B11,Verificacao!$A$24:$A$1367,0)),"")} | G11: {=IFERROR(INDEX(Verificacao!$N$24:$N$1367,MATCH($B11,Verificacao!$A$24:$A$1367,0)),"")} | H11: {=IFERROR(INDEX(Verificacao!$O$24:$O$1367,MATCH($B11,Verificacao!$A$24:$A$1367,0)),"")} | I11: {=IFERROR(INDEX(Verificacao!$J$24:$J$1367,MATCH($B11,Verificacao!$A$24:$A$1367,0)),"")} | J11: {=IFERROR(INDEX(Verificacao!$R$24:$R$1367,MATCH($B11,Verificacao!$A$24:$A$1367,0)),"")} | K11: {=IFERROR(INDEX(Verificacao!$S$24:$S$1367,MATCH($B11,Verificacao!$A$24:$A$1367,0)),"")} | L11: {=IFERROR(INDEX(Verificacao!$T$24:$T$1367,MATCH($B11,Verificacao!$A$24:$A$1367,0)),"")} | M11: {=IFERROR(INDEX(Verificacao!$U$24:$U$1367,MATCH($B11,Verificacao!$A$24:$A$1367,0)),"")} | N11: {=IFERROR(INDEX(Verificacao!$V$24:$V$1367,MATCH($B11,Verificacao!$A$24:$A$1367,0)),"")} | O11: {=IFERROR(INDEX(Verificacao!$W$24:$W$1367,MATCH($B11,Verificacao!$A$24:$A$1367,0)),"")} | Q11: =IF(OR(P11="",M11=""),"",P11-M11) | S11: =IF(OR(R11="",H11=""),"",R11-H11) | U11: =IF(OR(T11="",L11=""),"",T11-L11)
A12: MAI | B12: =DATE($B$5,5,1) -> 3774 | C12: {=IFERROR(INDEX(Verificacao!$D$24:$D$1367,MATCH($B12,Verificacao!$A$24:$A$1367,0)),"")} | D12: {=IFERROR(INDEX(Verificacao!$E$24:$E$1367,MATCH($B12,Verificacao!$A$24:$A$1367,0)),"")} | E12: {=IFERROR(INDEX(Verificacao!$H$24:$H$1367,MATCH($B12,Verificacao!$A$24:$A$1367,0)),"")} | F12: {=IFERROR(INDEX(Verificacao!$F$24:$F$1367,MATCH($B12,Verificacao!$A$24:$A$1367,0)),"")} | G12: {=IFERROR(INDEX(Verificacao!$N$24:$N$1367,MATCH($B12,Verificacao!$A$24:$A$1367,0)),"")} | H12: {=IFERROR(INDEX(Verificacao!$O$24:$O$1367,MATCH($B12,Verificacao!$A$24:$A$1367,0)),"")} | I12: {=IFERROR(INDEX(Verificacao!$J$24:$J$1367,MATCH($B12,Verificacao!$A$24:$A$1367,0)),"")} | J12: {=IFERROR(INDEX(Verificacao!$R$24:$R$1367,MATCH($B12,Verificacao!$A$24:$A$1367,0)),"")} | K12: {=IFERROR(INDEX(Verificacao!$S$24:$S$1367,MATCH($B12,Verificacao!$A$24:$A$1367,0)),"")} | L12: {=IFERROR(INDEX(Verificacao!$T$24:$T$1367,MATCH($B12,Verificacao!$A$24:$A$1367,0)),"")} | M12: {=IFERROR(INDEX(Verificacao!$U$24:$U$1367,MATCH($B12,Verificacao!$A$24:$A$1367,0)),"")} | N12: {=IFERROR(INDEX(Verificacao!$V$24:$V$1367,MATCH($B12,Verificacao!$A$24:$A$1367,0)),"")} | O12: {=IFERROR(INDEX(Verificacao!$W$24:$W$1367,MATCH($B12,Verificacao!$A$24:$A$1367,0)),"")} | Q12: =IF(OR(P12="",M12=""),"",P12-M12) | S12: =IF(OR(R12="",H12=""),"",R12-H12) | U12: =IF(OR(T12="",L12=""),"",T12-L12)
A13: JUN | B13: =DATE($B$5,6,1) -> 3805 | C13: {=IFERROR(INDEX(Verificacao!$D$24:$D$1367,MATCH($B13,Verificacao!$A$24:$A$1367,0)),"")} | D13: {=IFERROR(INDEX(Verificacao!$E$24:$E$1367,MATCH($B13,Verificacao!$A$24:$A$1367,0)),"")} | E13: {=IFERROR(INDEX(Verificacao!$H$24:$H$1367,MATCH($B13,Verificacao!$A$24:$A$1367,0)),"")} | F13: {=IFERROR(INDEX(Verificacao!$F$24:$F$1367,MATCH($B13,Verificacao!$A$24:$A$1367,0)),"")} | G13: {=IFERROR(INDEX(Verificacao!$N$24:$N$1367,MATCH($B13,Verificacao!$A$24:$A$1367,0)),"")} | H13: {=IFERROR(INDEX(Verificacao!$O$24:$O$1367,MATCH($B13,Verificacao!$A$24:$A$1367,0)),"")} | I13: {=IFERROR(INDEX(Verificacao!$J$24:$J$1367,MATCH($B13,Verificacao!$A$24:$A$1367,0)),"")} | J13: {=IFERROR(INDEX(Verificacao!$R$24:$R$1367,MATCH($B13,Verificacao!$A$24:$A$1367,0)),"")} | K13: {=IFERROR(INDEX(Verificacao!$S$24:$S$1367,MATCH($B13,Verificacao!$A$24:$A$1367,0)),"")} | L13: {=IFERROR(INDEX(Verificacao!$T$24:$T$1367,MATCH($B13,Verificacao!$A$24:$A$1367,0)),"")} | M13: {=IFERROR(INDEX(Verificacao!$U$24:$U$1367,MATCH($B13,Verificacao!$A$24:$A$1367,0)),"")} | N13: {=IFERROR(INDEX(Verificacao!$V$24:$V$1367,MATCH($B13,Verificacao!$A$24:$A$1367,0)),"")} | O13: {=IFERROR(INDEX(Verificacao!$W$24:$W$1367,MATCH($B13,Verificacao!$A$24:$A$1367,0)),"")} | Q13: =IF(OR(P13="",M13=""),"",P13-M13) | S13: =IF(OR(R13="",H13=""),"",R13-H13) | U13: =IF(OR(T13="",L13=""),"",T13-L13)
A14: JUL | B14: =DATE($B$5,7,1) -> 3835 | C14: {=IFERROR(INDEX(Verificacao!$D$24:$D$1367,MATCH($B14,Verificacao!$A$24:$A$1367,0)),"")} | D14: {=IFERROR(INDEX(Verificacao!$E$24:$E$1367,MATCH($B14,Verificacao!$A$24:$A$1367,0)),"")} | E14: {=IFERROR(INDEX(Verificacao!$H$24:$H$1367,MATCH($B14,Verificacao!$A$24:$A$1367,0)),"")} | F14: {=IFERROR(INDEX(Verificacao!$F$24:$F$1367,MATCH($B14,Verificacao!$A$24:$A$1367,0)),"")} | G14: {=IFERROR(INDEX(Verificacao!$N$24:$N$1367,MATCH($B14,Verificacao!$A$24:$A$1367,0)),"")} | H14: {=IFERROR(INDEX(Verificacao!$O$24:$O$1367,MATCH($B14,Verificacao!$A$24:$A$1367,0)),"")} | I14: {=IFERROR(INDEX(Verificacao!$J$24:$J$1367,MATCH($B14,Verificacao!$A$24:$A$1367,0)),"")} | J14: {=IFERROR(INDEX(Verificacao!$R$24:$R$1367,MATCH($B14,Verificacao!$A$24:$A$1367,0)),"")} | K14: {=IFERROR(INDEX(Verificacao!$S$24:$S$1367,MATCH($B14,Verificacao!$A$24:$A$1367,0)),"")} | L14: {=IFERROR(INDEX(Verificacao!$T$24:$T$1367,MATCH($B14,Verificacao!$A$24:$A$1367,0)),"")} | M14: {=IFERROR(INDEX(Verificacao!$U$24:$U$1367,MATCH($B14,Verificacao!$A$24:$A$1367,0)),"")} | N14: {=IFERROR(INDEX(Verificacao!$V$24:$V$1367,MATCH($B14,Verificacao!$A$24:$A$1367,0)),"")} | O14: {=IFERROR(INDEX(Verificacao!$W$24:$W$1367,MATCH($B14,Verificacao!$A$24:$A$1367,0)),"")} | Q14: =IF(OR(P14="",M14=""),"",P14-M14) | S14: =IF(OR(R14="",H14=""),"",R14-H14) | U14: =IF(OR(T14="",L14=""),"",T14-L14)
A15: AGO | B15: =DATE($B$5,8,1) -> 3866 | C15: {=IFERROR(INDEX(Verificacao!$D$24:$D$1367,MATCH($B15,Verificacao!$A$24:$A$1367,0)),"")} | D15: {=IFERROR(INDEX(Verificacao!$E$24:$E$1367,MATCH($B15,Verificacao!$A$24:$A$1367,0)),"")} | E15: {=IFERROR(INDEX(Verificacao!$H$24:$H$1367,MATCH($B15,Verificacao!$A$24:$A$1367,0)),"")} | F15: {=IFERROR(INDEX(Verificacao!$F$24:$F$1367,MATCH($B15,Verificacao!$A$24:$A$1367,0)),"")} | G15: {=IFERROR(INDEX(Verificacao!$N$24:$N$1367,MATCH($B15,Verificacao!$A$24:$A$1367,0)),"")} | H15: {=IFERROR(INDEX(Verificacao!$O$24:$O$1367,MATCH($B15,Verificacao!$A$24:$A$1367,0)),"")} | I15: {=IFERROR(INDEX(Verificacao!$J$24:$J$1367,MATCH($B15,Verificacao!$A$24:$A$1367,0)),"")} | J15: {=IFERROR(INDEX(Verificacao!$R$24:$R$1367,MATCH($B15,Verificacao!$A$24:$A$1367,0)),"")} | K15: {=IFERROR(INDEX(Verificacao!$S$24:$S$1367,MATCH($B15,Verificacao!$A$24:$A$1367,0)),"")} | L15: {=IFERROR(INDEX(Verificacao!$T$24:$T$1367,MATCH($B15,Verificacao!$A$24:$A$1367,0)),"")} | M15: {=IFERROR(INDEX(Verificacao!$U$24:$U$1367,MATCH($B15,Verificacao!$A$24:$A$1367,0)),"")} | N15: {=IFERROR(INDEX(Verificacao!$V$24:$V$1367,MATCH($B15,Verificacao!$A$24:$A$1367,0)),"")} | O15: {=IFERROR(INDEX(Verificacao!$W$24:$W$1367,MATCH($B15,Verificacao!$A$24:$A$1367,0)),"")} | Q15: =IF(OR(P15="",M15=""),"",P15-M15) | S15: =IF(OR(R15="",H15=""),"",R15-H15) | U15: =IF(OR(T15="",L15=""),"",T15-L15)
A16: SET | B16: =DATE($B$5,9,1) -> 3897 | C16: {=IFERROR(INDEX(Verificacao!$D$24:$D$1367,MATCH($B16,Verificacao!$A$24:$A$1367,0)),"")} | D16: {=IFERROR(INDEX(Verificacao!$E$24:$E$1367,MATCH($B16,Verificacao!$A$24:$A$1367,0)),"")} | E16: {=IFERROR(INDEX(Verificacao!$H$24:$H$1367,MATCH($B16,Verificacao!$A$24:$A$1367,0)),"")} | F16: {=IFERROR(INDEX(Verificacao!$F$24:$F$1367,MATCH($B16,Verificacao!$A$24:$A$1367,0)),"")} | G16: {=IFERROR(INDEX(Verificacao!$N$24:$N$1367,MATCH($B16,Verificacao!$A$24:$A$1367,0)),"")} | H16: {=IFERROR(INDEX(Verificacao!$O$24:$O$1367,MATCH($B16,Verificacao!$A$24:$A$1367,0)),"")} | I16: {=IFERROR(INDEX(Verificacao!$J$24:$J$1367,MATCH($B16,Verificacao!$A$24:$A$1367,0)),"")} | J16: {=IFERROR(INDEX(Verificacao!$R$24:$R$1367,MATCH($B16,Verificacao!$A$24:$A$1367,0)),"")} | K16: {=IFERROR(INDEX(Verificacao!$S$24:$S$1367,MATCH($B16,Verificacao!$A$24:$A$1367,0)),"")} | L16: {=IFERROR(INDEX(Verificacao!$T$24:$T$1367,MATCH($B16,Verificacao!$A$24:$A$1367,0)),"")} | M16: {=IFERROR(INDEX(Verificacao!$U$24:$U$1367,MATCH($B16,Verificacao!$A$24:$A$1367,0)),"")} | N16: {=IFERROR(INDEX(Verificacao!$V$24:$V$1367,MATCH($B16,Verificacao!$A$24:$A$1367,0)),"")} | O16: {=IFERROR(INDEX(Verificacao!$W$24:$W$1367,MATCH($B16,Verificacao!$A$24:$A$1367,0)),"")} | Q16: =IF(OR(P16="",M16=""),"",P16-M16) | S16: =IF(OR(R16="",H16=""),"",R16-H16) | U16: =IF(OR(T16="",L16=""),"",T16-L16)
A17: OUT | B17: =DATE($B$5,10,1) -> 3927 | C17: {=IFERROR(INDEX(Verificacao!$D$24:$D$1367,MATCH($B17,Verificacao!$A$24:$A$1367,0)),"")} | D17: {=IFERROR(INDEX(Verificacao!$E$24:$E$1367,MATCH($B17,Verificacao!$A$24:$A$1367,0)),"")} | E17: {=IFERROR(INDEX(Verificacao!$H$24:$H$1367,MATCH($B17,Verificacao!$A$24:$A$1367,0)),"")} | F17: {=IFERROR(INDEX(Verificacao!$F$24:$F$1367,MATCH($B17,Verificacao!$A$24:$A$1367,0)),"")} | G17: {=IFERROR(INDEX(Verificacao!$N$24:$N$1367,MATCH($B17,Verificacao!$A$24:$A$1367,0)),"")} | H17: {=IFERROR(INDEX(Verificacao!$O$24:$O$1367,MATCH($B17,Verificacao!$A$24:$A$1367,0)),"")} | I17: {=IFERROR(INDEX(Verificacao!$J$24:$J$1367,MATCH($B17,Verificacao!$A$24:$A$1367,0)),"")} | J17: {=IFERROR(INDEX(Verificacao!$R$24:$R$1367,MATCH($B17,Verificacao!$A$24:$A$1367,0)),"")} | K17: {=IFERROR(INDEX(Verificacao!$S$24:$S$1367,MATCH($B17,Verificacao!$A$24:$A$1367,0)),"")} | L17: {=IFERROR(INDEX(Verificacao!$T$24:$T$1367,MATCH($B17,Verificacao!$A$24:$A$1367,0)),"")} | M17: {=IFERROR(INDEX(Verificacao!$U$24:$U$1367,MATCH($B17,Verificacao!$A$24:$A$1367,0)),"")} | N17: {=IFERROR(INDEX(Verificacao!$V$24:$V$1367,MATCH($B17,Verificacao!$A$24:$A$1367,0)),"")} | O17: {=IFERROR(INDEX(Verificacao!$W$24:$W$1367,MATCH($B17,Verificacao!$A$24:$A$1367,0)),"")} | Q17: =IF(OR(P17="",M17=""),"",P17-M17) | S17: =IF(OR(R17="",H17=""),"",R17-H17) | U17: =IF(OR(T17="",L17=""),"",T17-L17)
A18: NOV | B18: =DATE($B$5,11,1) -> 3958 | C18: {=IFERROR(INDEX(Verificacao!$D$24:$D$1367,MATCH($B18,Verificacao!$A$24:$A$1367,0)),"")} -> 0 | D18: {=IFERROR(INDEX(Verificacao!$E$24:$E$1367,MATCH($B18,Verificacao!$A$24:$A$1367,0)),"")} -> 0 | E18: {=IFERROR(INDEX(Verificacao!$H$24:$H$1367,MATCH($B18,Verificacao!$A$24:$A$1367,0)),"")} -> 10.65 | F18: {=IFERROR(INDEX(Verificacao!$F$24:$F$1367,MATCH($B18,Verificacao!$A$24:$A$1367,0)),"")} -> 225.9 | G18: {=IFERROR(INDEX(Verificacao!$N$24:$N$1367,MATCH($B18,Verificacao!$A$24:$A$1367,0)),"")} -> 0.92601466 | H18: {=IFERROR(INDEX(Verificacao!$O$24:$O$1367,MATCH($B18,Verificacao!$A$24:$A$1367,0)),"")} -> 0.20918671 | I18: {=IFERROR(INDEX(Verificacao!$J$24:$J$1367,MATCH($B18,Verificacao!$A$24:$A$1367,0)),"")} -> 0.5 | J18: {=IFERROR(INDEX(Verificacao!$R$24:$R$1367,MATCH($B18,Verificacao!$A$24:$A$1367,0)),"")} -> 0.5 | K18: {=IFERROR(INDEX(Verificacao!$S$24:$S$1367,MATCH($B18,Verificacao!$A$24:$A$1367,0)),"")} -> 0 | L18: {=IFERROR(INDEX(Verificacao!$T$24:$T$1367,MATCH($B18,Verificacao!$A$24:$A$1367,0)),"")} -> 0 | M18: {=IFERROR(INDEX(Verificacao!$U$24:$U$1367,MATCH($B18,Verificacao!$A$24:$A$1367,0)),"")} -> 9.1448133 | N18: {=IFERROR(INDEX(Verificacao!$V$24:$V$1367,MATCH($B18,Verificacao!$A$24:$A$1367,0)),"")} -> Não | O18: {=IFERROR(INDEX(Verificacao!$W$24:$W$1367,MATCH($B18,Verificacao!$A$24:$A$1367,0)),"")} -> 0 | Q18: =IF(OR(P18="",M18=""),"",P18-M18) | S18: =IF(OR(R18="",H18=""),"",R18-H18) | U18: =IF(OR(T18="",L18=""),"",T18-L18)
A19: DEZ | B19: =DATE($B$5,12,1) -> 3988 | C19: {=IFERROR(INDEX(Verificacao!$D$24:$D$1367,MATCH($B19,Verificacao!$A$24:$A$1367,0)),"")} -> 0 | D19: {=IFERROR(INDEX(Verificacao!$E$24:$E$1367,MATCH($B19,Verificacao!$A$24:$A$1367,0)),"")} -> 0 | E19: {=IFERROR(INDEX(Verificacao!$H$24:$H$1367,MATCH($B19,Verificacao!$A$24:$A$1367,0)),"")} -> 10.65 | F19: {=IFERROR(INDEX(Verificacao!$F$24:$F$1367,MATCH($B19,Verificacao!$A$24:$A$1367,0)),"")} -> 206 | G19: {=IFERROR(INDEX(Verificacao!$N$24:$N$1367,MATCH($B19,Verificacao!$A$24:$A$1367,0)),"")} -> 0.92632871 | H19: {=IFERROR(INDEX(Verificacao!$O$24:$O$1367,MATCH($B19,Verificacao!$A$24:$A$1367,0)),"")} -> 0.19082371 | I19: {=IFERROR(INDEX(Verificacao!$J$24:$J$1367,MATCH($B19,Verificacao!$A$24:$A$1367,0)),"")} -> 0.5 | J19: {=IFERROR(INDEX(Verificacao!$R$24:$R$1367,MATCH($B19,Verificacao!$A$24:$A$1367,0)),"")} -> 0.5 | K19: {=IFERROR(INDEX(Verificacao!$S$24:$S$1367,MATCH($B19,Verificacao!$A$24:$A$1367,0)),"")} -> 0 | L19: {=IFERROR(INDEX(Verificacao!$T$24:$T$1367,MATCH($B19,Verificacao!$A$24:$A$1367,0)),"")} -> 0 | M19: {=IFERROR(INDEX(Verificacao!$U$24:$U$1367,MATCH($B19,Verificacao!$A$24:$A$1367,0)),"")} -> 9.1631763 | N19: {=IFERROR(INDEX(Verificacao!$V$24:$V$1367,MATCH($B19,Verificacao!$A$24:$A$1367,0)),"")} -> Não | O19: {=IFERROR(INDEX(Verificacao!$W$24:$W$1367,MATCH($B19,Verificacao!$A$24:$A$1367,0)),"")} -> 0 | Q19: =IF(OR(P19="",M19=""),"",P19-M19) | S19: =IF(OR(R19="",H19=""),"",R19-H19) | U19: =IF(OR(T19="",L19=""),"",T19-L19)

Sheet Dados_Acudes
A1: CORPO | B1: COD | C1: CAPAC_M3 | D1: MUNICIPIO | E1: BACIA | F1: EstEvap | G1: CSANGR | H1: CTOMADA | I1: LSANGR | J1: COEFSAGR | K1: AUX_CAV_INICIO | L1: AUX_CAV_QTD
A2: Acarape do Meio | B2: 78 | C2: 29600000 | D2: Redenção | E2: 10 | F2: 6 | G2: 130.02 | H2: 105.5 | I2: 53 | J2: 1.71 | K2: 1491 | L2: 32
A3: Acaraú Mirim | B3: 1 | C3: 36715658 | D3: Massapê | E3: 6 | F3: 11 | G3: 115 | H3: 106.5 | I3: 60 | J3: 1.6 | K3: 2 | L3: 17
A4: Adauto Bezerra | B4: 32 | C4: 4790000 | D4: Pereiro | E4: 4 | F4: 1 | G4: 100 | I4: 24 | J4: 1.6 | K4: 668 | L4: 13
A5: Amanary | B5: 45 | C5: 11010000 | D5: Maranguape | E5: 10 | F5: 13 | G5: 96 | I5: 19 | J5: 1.71 | K5: 858 | L5: 17
A6: Angicos | B6: 112 | C6: 56050000 | D6: Coreaú | E6: 7 | F6: 11 | G6: 105.5 | H6: 97.17 | I6: 100 | J6: 2 | K6: 1940 | L6: 22
A7: Aracoiaba | B7: 234 | C7: 162000000 | D7: Aracoiaba | E7: 10 | F7: 10 | G7: 95 | H7: 75 | I7: 32 | J7: 1.6 | K7: 3430 | L7: 24
A8: Araras | B8: 31 | C8: 859533000 | D8: Varjota | E8: 6 | F8: 11 | G8: 153 | H8: 129.5 | I8: 265 | J8: 2 | K8: 630 | L8: 38
A9: Arneiroz II | B9: 240 | C9: 187700000 | D9: Arneiroz | E9: 1 | F9: 12 | G9: 368 | H9: 345 | I9: 300 | J9: 1.6 | K9: 3528 | L9: 22
A10: Arrebita | B10: 83 | C10: 18530000 | D10: Forquilha | E10: 6 | F10: 11 | G10: 112 | H10: 102 | I10: 70 | J10: 1.6 | K10: 1599 | L10: 21
A11: Atalho | B11: 47 | C11: 72552000 | D11: Brejo Santo | E11: 2 | F11: 2 | G11: 425 | H11: 400 | I11: 90 | J11: 2 | K11: 890 | L11: 39
A12: Ayres de Sousa | B12: 49 | C12: 96800000 | D12: Sobral | E12: 6 | F12: 11 | G12: 95 | H12: 82 | I12: 106.05 | J12: 2 | K12: 941 | L12: 54
A13: Banabuiú | B13: 2 | C13: 1601000000 | D13: Banabuiú | E13: 3 | F13: 10 | G13: 142.5 | H13: 94.12 | I13: 100 | J13: 2 | K13: 19 | L13: 30
A14: Barra Velha | B14: 163 | C14: 99560000 | D14: Independência | E14: 9 | F14: 4 | G14: 333.6 | H14: 324.5 | I14: 310 | J14: 1.6 | K14: 2496 | L14: 19
A15: Barragem do Batalhão | B15: 202 | C15: 1638800 | D15: Crateús | E15: 9 | F15: 4 | G15: 99.85 | H15: 97.7 | I15: 600 | K15: 3121 | L15: 15
A16: Batente | B16: 173 | C16: 37000000 | D16: Ocara | E16: 10 | F16: 9 | G16: 71.86 | I16: 180 | K16: 2669 | L16: 18
A17: Benguê | B17: 177 | C17: 18425000 | D17: Aiuaba | E17: 1 | F17: 3 | G17: 448.54 | H17: 438 | I17: 150 | J17: 2 | K17: 2717 | L17: 28
A18: Bonito | B18: 64 | C18: 6000000 | D18: Ipú | E18: 6 | F18: 4 | G18: 104.5 | H18: 99 | J18: 1.6 | K18: 1224 | L18: 14
A19: Broco | B19: 125 | C19: 8442000 | D19: Tauá | E19: 1 | F19: 12 | G19: 100 | H19: 96 | K19: 2101 | L19: 16
A20: Cachoeira | B20: 170 | C20: 34330000 | D20: Aurora | E20: 2 | F20: 2 | G20: 305 | H20: 289 | I20: 76 | J20: 2 | K20: 2611 | L20: 20
A21: Caldeirões | B21: 217 | C21: 1130000 | D21: Saboeiro | E21: 1 | F21: 12 | G21: 100 | I21: 257.8 | J21: 1.2 | K21: 3360 | L21: 13
A22: Canafístula | B22: 74 | C22: 13110000 | D22: Iracema | E22: 4 | F22: 1 | G22: 101 | H22: 94.5 | I22: 60 | J22: 1.6 | K22: 1431 | L22: 14
A23: Canoas | B23: 127 | C23: 69250000 | D23: Assaré | E23: 1 | F23: 3 | G23: 393 | H23: 354 | I23: 50 | J23: 2 | K23: 2133 | L23: 42
A24: Capitão Mor | B24: 33 | C24: 6000000 | D24: Pedra Branca | E24: 3 | F24: 12 | G24: 97.3 | H24: 90 | I24: 90 | J24: 1.6 | K24: 681 | L24: 24
A25: Carão | B25: 65 | C25: 26230000 | D25: Tamboril | E25: 6 | F25: 4 | G25: 96 | H25: 86.5 | I25: 192.9 | J25: 1.6 | K25: 1238 | L25: 16
A26: Carmina | B26: 236 | C26: 13480000 | D26: Catunda | E26: 6 | F26: 4 | G26: 280 | H26: 267 | I26: 65 | J26: 1.6 | K26: 3473 | L26: 21
A27: Carnaubal | B27: 53 | C27: 46621000 | D27: Crateús | E27: 9 | F27: 4 | G27: 300 | H27: 290 | I27: 200 | J27: 2 | K27: 1055 | L27: 18
A28: Castanhão | B28: 194 | C28: 6700000000 | D28: Alto Santo | E28: 4 | F28: 9 | G28: 106 | H28: 57 | I28: 153 | J28: 2 | K28: 2962 | L28: 103
A29: Castro | B29: 97 | C29: 62310000 | D29: Itapiúna | E29: 10 | F29: 10 | G29: 151.5 | H29: 137 | I29: 80 | J29: 2 | K29: 1846 | L29: 16
A30: Catucinzenta | B30: 223 | C30: 24900000 | D30: Aquiraz | E30: 10 | F30: 5 | G30: 45 | H30: 38.13 | I30: 50 | J30: 2 | K30: 3399 | L30: 18
A31: Cauhipe | B31: 158 | C31: 12000000 | D31: Caucaia | E31: 10 | F31: 13 | G31: 36.89 | H31: 31.5 | I31: 120 | J31: 2 | K31: 2417 | L31: 13
A32: Caxitoré | B32: 3 | C32: 202000000 | D32: Umirim | E32: 8 | F32: 13 | G32: 73 | H32: 55 | I32: 63.6 | J32: 1.6 | K32: 49 | L32: 33
A33: Cedro | B33: 4 | C33: 126000000 | D33: Quixadá | E33: 3 | F33: 10 | G33: 114.5 | H33: 100.5 | I33: 75.27 | J33: 2 | K33: 82 | L33: 27
